Workbook

Sheet Inputs
A1: INPUTS | B1: Отрасль | C1: Подотрасль/ Дивизион | D1: Источник | E1: Дата обновления | F1: Наименование | G1: Ед. измерения | H1: Link | I1: Комментарий к заполнению (формула) | J1: 2001 | K1: 2002 | L1: 2003 | M1: 2004 | N1: 2005 | O1: 2006 | P1: 2007 | Q1: 2008 | R1: 2009 | S1: 2010 | T1: 2011 | U1: 2012 | V1: 2013 | W1: 2014 | X1: 2015 | Y1: 2016 | Z1: 2017 | AA1: 2018 | AB1: 2019 | AC1: 2020 | AD1: 2021 | AE1: 2022 | AF1: 2023 | AG1: 2024 | AH1: 2025 | AI1: 2026 | AJ1: 2027 | AK1: 2028 | AL1: 2029 | AM1: 2030 | AN1: 2031 | AO1: 2032 | AP1: 2033 | AQ1: 2034 | AR1: 2035 | AS1: 2036 | AT1: 2037 | AU1: 2038 | AV1: 2039 | AW1: 2040 | AX1: 2041 | AY1: 2042 | AZ1: 2043 | BA1: 2044 | BB1: 2045 | BC1: 2046 | BD1: 2047 | BE1: 2048 | BF1: 2049 | BG1: 2050
A2: Общие | D2: ЦМИ | F2: Рост реального ВВП | G2: % | H2: Наименование листа, номер строки [например: Scenarios, line 352] | I2: Базовый 11.09.2026 | J2: 0.051 | K2: 0.047 | L2: 0.072956141 | M2: 0.07175933 | N2: 0.063764415 | O2: 0.081534248 | P2: 0.085350329 | Q2: 0.052477517 | R2: -0.078208582 | S2: 0.045037137 | T2: 0.042643516 | U2: 0.036559016 | V2: 0.017853545 | W2: 0.0073860077 | X2: -0.025383168 | Y2: 0.0028878412 | Z2: 0.016468837 | AA2: 0.028063408 | AB2: 0.020329827 | AC2: -0.026536545 | AD2: 0.059 | AE2: -0.014359355 | AF2: 0.0407 | AG2: 0.0492 | AH2: 0.01 | AI2: 0.0063 | AJ2: 0.0139 | AK2: 0.0163 | AL2: 0.0182 | AM2: 0.0182 | AN2: =AM2 -> 0.0182 | AO2: =AN2 -> 0.0182 | AP2: =AO2 -> 0.0182 | AQ2: =AP2 -> 0.0182 | AR2: =AQ2 -> 0.0182 | AS2: =AR2 -> 0.0182 | AT2: =AS2 -> 0.0182 | AU2: =AT2 -> 0.0182 | ... BG2: =BF2 -> 0.0182
A3: Общие | D3: ЦМИ | F3: Инфляция - Рост индекса потребительских цен (RUB, eop CPI) | G3: % | I3: С 2021 года прогноз CIB | J3: 0.1858 | K3: 0.1506 | L3: 0.1199 | M3: 0.1173 | N3: 0.1092 | O3: 0.09 | P3: 0.1187 | Q3: 0.1328 | R3: 0.088 | S3: 0.0878 | T3: 0.061 | U3: 0.066 | V3: 0.065 | W3: 0.1135 | X3: 0.1291 | Y3: 0.0539 | Z3: 0.0251 | AA3: 0.0426 | AB3: 0.0304 | AC3: 0.0491 | AD3: 0.083930153 | AE3: 0.11922836 | AF3: 0.0742 | AG3: 0.0952 | AH3: 0.0559 | AI3: 0.067380961 | AJ3: 0.047439689 | AK3: 0.040050205 | AL3: 0.039847139 | AM3: 0.03995079 | AN3: 0.04 | AO3: =AN3 -> 0.04 | AP3: =AO3 -> 0.04 | AQ3: =AP3 -> 0.04 | AR3: =AQ3 -> 0.04 | AS3: =AR3 -> 0.04 | AT3: =AS3 -> 0.04 | AU3: =AT3 -> 0.04 | AV3: =AU3 -> 0.04 | ... BG3: =BF3 -> 0.04
A4: Общие | D4: CIB Research | F4: Инфляция - Рост индекса потребительских цен в США, в долларах США (USD, eop CPI) | G4: % | I4: EoY PCE, source: FX/IR team | J4: 0.0172429 | K4: 0.0172766 | L4: 0.0141467 | M4: 0.021474 | N4: 0.0219964 | O4: 0.0222292 | P4: 0.0233468 | Q4: 0.0135128 | R4: 0.0161556 | S4: 0.0090211 | T4: 0.0205826 | U4: 0.0171363 | V4: 0.016331 | W4: 0.0075649327 | X4: 0.0063871458 | Y4: 0.020507924 | Z4: 0.021299357 | AA4: 0.020023707 | AB4: 0.023195291 | AC4: 0.013049536 | AD4: 0.071765966 | AE4: 0.064115004 | AF4: 0.03323156 | AG4: 0.028723677 | AH4: 0.026899449 | AI4: 0.027326387 | AJ4: 0.026069089 | AK4: 0.022921913 | AL4: 0.01939121 | AM4: 0.02235396 | AN4: 0.02 | AO4: 0.02 | AP4: 0.02 | AQ4: 0.02 | AR4: 0.02 | AS4: 0.02 | AT4: 0.02 | AU4: 0.02 | AV4: 0.02 | AW4: 0.02 | AX4: 0.02 | AY4: 0.02 | AZ4: 0.02 | BA4: 0.02 | BB4: 0.02 | BC4: =BB4 -> 0.02 | BD4: =BC4 -> 0.02 | BE4: =BD4 -> 0.02 | BF4: =BE4 -> 0.02 | BG4: =BF4 -> 0.02
A5: Общие | D5: ЦМИ | F5: Инфляция - Рост индекса цен производителей (RUB, eop PPI) | G5: % | I5: С 2021 года прогноз CIB | J5: 0.0833 | K5: 0.1765 | L5: 0.1254 | M5: 0.2883 | N5: 0.1335 | O5: 0.1037 | P5: 0.2507 | Q5: -0.07 | R5: 0.1385 | S5: 0.1666 | T5: 0.1201 | U5: 0.051 | V5: 0.0346 | W5: 0.0628 | X5: 0.1214 | Y5: 0.0745 | Z5: 0.0837 | AA5: 0.1171 | AB5: -0.0426 | AC5: 0.0356 | AD5: 0.2852 | AE5: -0.033181437 | AF5: 0.1916 | AG5: 0.0791 | AH5: -0.0328 | AI5: 0.12373075 | AJ5: 0.048265541 | AK5: 0.087119187 | AL5: 0.053103144 | AM5: 0.056887074 | AN5: 0.04 | AO5: =AN5 -> 0.04 | AP5: =AO5 -> 0.04 | AQ5: =AP5 -> 0.04 | AR5: =AQ5 -> 0.04 | AS5: =AR5 -> 0.04 | AT5: =AS5 -> 0.04 | AU5: =AT5 -> 0.04 | AV5: =AU5 -> 0.04 | ... BG5: =BF5 -> 0.04
A6: Общие | D6: ЦМИ | F6: Инфляция - Дефлятор ВВП (RUB, GDP Deflator) | G6: % | I6: =0.8CPI+0.2PPI; С 2021 года прогноз CIB | J6: 0.16489519 | K6: 0.15613926 | L6: 0.13780061 | M6: 0.20282077 | N6: 0.19306095 | O6: 0.15170047 | P6: 0.13804421 | Q6: 0.17959714 | R6: 0.019937228 | S6: 0.14187039 | T6: 0.15914448 | U6: 0.074 | V6: 0.05 | W6: 0.089 | X6: 0.079 | Y6: 0.035158922 | Z6: 0.044 | AA6: 0.099989476 | AB6: 0.030841738 | AC6: 0.0089826982 | AD6: 0.182 | AE6: 0.182 | AF6: 0.067 | AG6: 0.107 | AH6: 0.049 | AI6: 0.076830584 | AJ6: 0.033790794 | AK6: 0.052796743 | AL6: 0.063195192 | AM6: 0.048456871 | AN6: =0.8*AN3+0.2*AN5 -> 0.04 | AO6: =0.8*AO3+0.2*AO5 -> 0.04 | AP6: =0.8*AP3+0.2*AP5 -> 0.04 | AQ6: =0.8*AQ3+0.2*AQ5 -> 0.04 | AR6: =0.8*AR3+0.2*AR5 -> 0.04 | AS6: =0.8*AS3+0.2*AS5 -> 0.04 | AT6: =0.8*AT3+0.2*AT5 -> 0.04 | AU6: =0.8*AU3+0.2*AU5 -> 0.04 | ... BG6: =0.8*BG3+0.2*BG5 -> 0.04
A7: Общие | D7: Расчет | F7: Курс рубля к доллару США в конце года (eop USD/RUB) | G7: $/руб | I7: 2015-17 модель ЦМИ c ценой на нефть CIB Research, после - CIB Research, с 2019 года прогноз CIB; =предыдущий год*1.02 | J7: 30.14 | K7: 31.78 | L7: 29.45 | M7: 27.75 | N7: 28.78 | O7: 26.33 | P7: 24.55 | Q7: 29.38 | R7: 30.24 | S7: 30.48 | T7: 32.2 | U7: 30.37 | V7: 32.73 | W7: 56.2584 | X7: 72.8827 | Y7: 60.6569 | Z7: 57.6002 | AA7: 69.4706 | AB7: 61.9057 | AC7: 73.8757 | AD7: 74.2926 | AE7: 70.3375 | AF7: 89.69 | AG7: 101.68 | AH7: 78.23 | AI7: 88.047138 | AJ7: 93.201775 | AK7: 97.205694 | AL7: 101.36373 | AM7: 105.70549 | AN7: =AN14 -> 105.95911 | AO7: =AO14 -> 108.07829 | AP7: =AP14 -> 110.23985 | AQ7: =AQ14 -> 112.44465 | AR7: =AR14 -> 114.69354 | AS7: =AS14 -> 116.98741 | AT7: =AT14 -> 119.32716 | AU7: =AU14 -> 121.71371 | ... BG7: =BG14 -> 154.36241
A8: Общие | D8: Расчет | F8: Курс рубля к EUR в конце года (eop EUR/RUB) | G8: EUR/руб | I8: =EUR/USD*курс доллара | J8: 26.49 | K8: 33.11 | L8: 36.82 | M8: 37.81 | N8: 34.19 | O8: 34.7 | P8: 35.93 | Q8: 41.44 | R8: 43.39 | S8: 40.33 | T8: 41.67 | U8: 40.23 | V8: 44.97 | W8: 68.34 | X8: 79.56 | Y8: 63.8111 | Z8: 68.8668 | AA8: 79.4605 | AB8: 69.3406 | AC8: 90.6824 | AD8: 84.0695 | AE8: 75.6553 | AF8: 99.2 | AG8: 106.1028 | AH8: 92.097683 | AI8: =AI7*AI36 -> 102.13468 | AJ8: =AJ7*AJ36 -> 107.18204 | AK8: =AK7*AK36 -> 111.78655 | AL8: =AL7*AL36 -> 116.56829 | AM8: =AM7*AM36 -> 121.56131 | AN8: =AN7*AN36 -> 121.83983 | AO8: =AO7*AO36 -> 124.27662 | AP8: =AP7*AP36 -> 126.76215 | ... BG8: =BG7*BG36 -> 177.49762
A9: Общие | D9: ЦМИ | F9: Рост реальных расп. денежных доходов населения | G9: % | I9: С 2021 года прогноз CIB | J9: 0.087 | K9: 0.111 | L9: 0.15 | M9: 0.104 | N9: 0.124 | O9: 0.135 | P9: 0.121 | Q9: 0.024 | R9: 0.03 | S9: 0.059 | T9: 0.005 | U9: 0.058 | V9: 0.048 | W9: -0.012 | X9: -0.024 | Y9: -0.045 | Z9: -0.005 | AA9: 0.00675 | AB9: 0.01125 | AC9: -0.01975 | AD9: 0.032167843 | AE9: 0.045 | AF9: 0.060855091 | AG9: 0.082218231 | AH9: 0.074745567 | AI9: 0.019344246 | AJ9: 0.051262825 | AK9: 0.022596442 | AL9: 0.021191425 | AM9: 0.021023688 | AN9: =AM9 -> 0.021023688 | AO9: =AN9 -> 0.021023688 | AP9: =AO9 -> 0.021023688 | AQ9: =AP9 -> 0.021023688 | AR9: =AQ9 -> 0.021023688 | AS9: =AR9 -> 0.021023688 | AT9: =AS9 -> 0.021023688 | AU9: =AT9 -> 0.021023688 | ... BG9: =BF9 -> 0.021023688
A10: Общие | D10: ЦМИ | F10: Ставка Libor 3m | G10: % | I10: ЦМИ, 2022 и далее = 2021 | J10: 0.0188125 | K10: 0.0138 | L10: 0.0115188 | M10: 0.0256438 | N10: 0.0453625 | O10: 0.0536 | P10: 0.047025 | Q10: 0.01425 | R10: 0.0025063 | S10: 0.0030281 | T10: 0.00581 | U10: 0.0043006071 | V10: 0.0026720119 | W10: 0.002556 | X10: 0.006127 | Y10: 0.0099789 | Z10: 0.0169428 | AA10: 0.0280763 | AB10: 0.0190838 | AC10: 0.0024 | AD10: 0.0021 | AE10: 0.0477 | AF10: 0.0559301 | AG10: 0.0395 | AH10: 0.0295 | AI10: 0.0255 | AJ10: =AI10 -> 0.0255 | AK10: =AJ10 -> 0.0255 | AL10: =AK10 -> 0.0255 | AM10: =AL10 -> 0.0255 | AN10: =AM10 -> 0.0255 | AO10: =AN10 -> 0.0255 | AP10: =AO10 -> 0.0255 | AQ10: =AP10 -> 0.0255 | ... BG10: =BF10 -> 0.0255
A11: Общие | D11: ЦМИ | F11: Ставка Mosprime 3m | G11: % | I11: EoY | N11: 0.0622 | O11: 0.058 | P11: 0.0671 | Q11: 0.218 | R11: 0.0705 | S11: 0.0406 | T11: 0.0722 | U11: 0.070919919 | V11: 0.070100407 | W11: 0.10529433 | X11: 0.1179 | Y11: 0.1049 | Z11: 0.0788 | AA11: 0.0858 | AB11: 0.0645 | AC11: 0.0492 | AD11: 0.095 | AE11: 0.0841 | AF11: 0.0955 | AG11: 0.083 | AH11: 0.07 | AI11: 0.0655 | AJ11: =AI11+(AJ$39-AI$39) -> 0.048 | AK11: =AJ11+(AK$39-AJ$39) -> 0.023 | AL11: =AK11+(AL$39-AK$39) -> 0.018 | AM11: =AL11+(AM$39-AL$39) -> 0.018 | AN11: =AM11+(AN$39-AM$39) -> 0.018 | AO11: =AN11+(AO$39-AN$39) -> 0.018 | AP11: =AO11+(AP$39-AO$39) -> 0.018 | AQ11: =AP11+(AQ$39-AP$39) -> 0.018 | ... BG11: =BF11+(BG$39-BF$39) -> 0.018
A12: Общие | D12: Законодательство | F12: Ставка НДС | G12: % | I12: С 2019 года прогноз CIB | U12: 0.18 | V12: 0.18 | W12: 0.18 | X12: 0.18 | Y12: 0.18 | Z12: 0.18 | AA12: 0.18 | AB12: 0.2 | AC12: 0.2 | AD12: 0.2 | AE12: 0.2 | AF12: 0.2 | AG12: 0.2 | AH12: =AG12 -> 0.2 | AI12: 0.22 | AJ12: =AI12 -> 0.22 | AK12: =AJ12 -> 0.22 | AL12: =AK12 -> 0.22 | AM12: =AL12 -> 0.22 | AN12: =AM12 -> 0.22 | AO12: =AN12 -> 0.22 | AP12: =AO12 -> 0.22 | AQ12: =AP12 -> 0.22 | ... BG12: =BF12 -> 0.22
A13: Общие | D13: Законодательство | F13: Ставка НДФЛ | G13: % | I13: Базовая ставка при доходе до 200 тыс. руб./мес, далее прогрессивная шкала | U13: 0.13 | V13: 0.13 | W13: 0.13 | X13: 0.13 | Y13: 0.13 | Z13: 0.13 | AA13: 0.13 | AB13: 0.13 | AC13: 0.13 | AD13: 0.13 | AE13: 0.13 | AF13: 0.13 | AG13: 0.13 | AH13: =AG13 -> 0.13 | AI13: =AH13 -> 0.13 | AJ13: =AI13 -> 0.13 | AK13: =AJ13 -> 0.13 | AL13: =AK13 -> 0.13 | AM13: =AL13 -> 0.13 | AN13: =AM13 -> 0.13 | AO13: =AN13 -> 0.13 | ... BG13: =BF13 -> 0.13
A14: Общие | D14: ЦМИ | F14: Средний за период курс рубля к доллару США (av USD/RUB) | G14: $/руб | I14: С 2021 года прогноз CIB | J14: 29.17 | K14: 31.35 | L14: 30.68 | M14: 28.81 | N14: 28.7 | O14: 27.18 | P14: 25.57 | Q14: 24.81 | R14: 31.68 | S14: 30.36 | T14: 29.35 | U14: 31.07 | V14: 31.82 | W14: 38.378333 | X14: 60.938333 | Y14: 67.055 | Z14: 58.343333 | AA14: 62.668333 | AB14: 64.737642 | AC14: 72.104908 | AD14: 73.65435 | AE14: 68.485225 | AF14: 85.1725 | AG14: 92.552167 | AH14: 83.654167 | AI14: 80.61478 | AJ14: 91.367236 | AK14: 95.531033 | AL14: 99.616342 | AM14: 103.88148 | AN14: =AM14*(1+AN3-AN4) -> 105.95911 | AO14: =AN14*(1+AO3-AO4) -> 108.07829 | AP14: =AO14*(1+AP3-AP4) -> 110.23985 | AQ14: =AP14*(1+AQ3-AQ4) -> 112.44465 | AR14: =AQ14*(1+AR3-AR4) -> 114.69354 | AS14: =AR14*(1+AS3-AS4) -> 116.98741 | AT14: =AS14*(1+AT3-AT4) -> 119.32716 | AU14: =AT14*(1+AU3-AU4) -> 121.71371 | ... BG14: =BF14*(1+BG3-BG4) -> 154.36241
A15: Общие | D15: ЦМИ | F15: Средний за период курс рубля к EUR (av EUR/RUB) | G15: EUR/руб | I15: формула | J15: 26.13 | K15: 29.65 | L15: 34.69 | M15: 35.81 | N15: 34.17 | O15: 34.11 | P15: 35.01 | Q15: 36.41 | R15: 44.13 | S15: 40.27 | T15: 40.87 | U15: 39.93752 | V15: 42.382855 | W15: 51.019749 | X15: 67.762375 | Y15: 74.253684 | Z15: 65.855176 | AA15: 74.052364 | AB15: 72.4995 | AC15: 82.274762 | AD15: 87.189518 | AE15: 72.022339 | AF15: 92.151471 | AG15: 100.28011 | AH15: =AH14*AH35 -> 94.584736 | AI15: =AI14*AI35 -> 93.749206 | AJ15: =AJ14*AJ35 -> 105.42943 | AK15: =AK14*AK35 -> 109.8249 | AL15: =AL14*AL35 -> 114.57118 | AM15: =AM14*AM35 -> 119.45081 | AN15: =AN14*AN35 -> 121.83983 | AO15: =AO14*AO35 -> 124.27662 | ... BG15: =BG14*BG35 -> 177.49762
A16: Общие | D16: Законодательство | F16: Налог на имущество, инвентаризационная стоимость (НК Часть 2 Статья 380, максимальная ставка) | G16: % | I16: С 2019 года = 2018 | U16: 0.022 | V16: 0.022 | W16: 0.022 | X16: 0.022 | Y16: 0.022 | Z16: 0.022 | AA16: 0.022 | AB16: 0.022 | AC16: 0.022 | AD16: 0.022 | AE16: 0.022 | AF16: 0.022 | AG16: 0.022 | AH16: =AG16 -> 0.022 | AI16: =AH16 -> 0.022 | AJ16: =AI16 -> 0.022 | AK16: =AJ16 -> 0.022 | AL16: =AK16 -> 0.022 | AM16: =AL16 -> 0.022 | AN16: =AM16 -> 0.022 | AO16: =AN16 -> 0.022 | ... BG16: =BF16 -> 0.022
A17: Общие | D17: Законодательство | F17: Налог на имущество, кадастровая стоимость Москва (Закон г. Москвы от 05.11.2003 N 64, ред. от 25.11.2015, "О налоге на имущество организаций") | G17: % | I17: С 2019 года = 2018 | W17: 0.009 | X17: 0.012 | Y17: 0.013 | Z17: 0.014 | AA17: 0.015 | AB17: 0.016 | AC17: 0.017 | AD17: 0.018 | AE17: 0.019 | AF17: 0.02 | AG17: 0.02 | AH17: =AG17 -> 0.02 | AI17: =AH17 -> 0.02 | AJ17: =AI17 -> 0.02 | AK17: =AJ17 -> 0.02 | AL17: =AK17 -> 0.02 | AM17: =AL17 -> 0.02 | AN17: =AM17 -> 0.02 | AO17: =AN17 -> 0.02 | ... BG17: =BF17 -> 0.02
A18: Общие | D18: Законодательство | F18: Налог на имущество, кадастровая стоимость кроме Москвы (НК Часть 2 Статья 380, максимальная ставка) | G18: % | I18: С 2019 года = 2018 | W18: 0.01 | X18: 0.015 | Y18: 0.02 | Z18: 0.02 | AA18: 0.02 | AB18: 0.02 | AC18: 0.02 | AD18: 0.02 | AE18: 0.02 | AF18: 0.02 | AG18: 0.02 | AH18: =AG18 -> 0.02 | AI18: =AH18 -> 0.02 | AJ18: =AI18 -> 0.02 | AK18: =AJ18 -> 0.02 | AL18: =AK18 -> 0.02 | AM18: =AL18 -> 0.02 | AN18: =AM18 -> 0.02 | AO18: =AN18 -> 0.02 | ... BG18: =BF18 -> 0.02
A19: Общие | D19: ЦМИ | F19: Инфляция з.платы (Рост номинальных заработных плат) | G19: % | I19: С 2021 года прогноз CIB; =CPI+рост реальных доходов | J19: 0.457 | K19: 0.346 | L19: 0.261 | M19: 0.226 | N19: 0.269 | O19: 0.243 | P19: 0.278 | Q19: 0.272 | R19: 0.078 | S19: 0.124 | T19: 0.115 | U19: 0.139 | V19: 0.119 | W19: 0.091 | X19: 0.042392097 | Y19: 0.0802013 | Z19: 0.065530006 | AA19: 0.11009795 | AB19: 0.091798583 | AC19: 0.07603513 | AD19: 0.10656959 | AE19: 0.1564009 | AF19: 0.12639276 | AG19: 0.19323935 | AH19: 0.14083749 | AI19: 0.12048028 | AJ19: 0.087616212 | AK19: 0.067391121 | AL19: 0.0661684 | AM19: 0.065929549 | AN19: =(1+AN9)*(1+AN3)-1 -> 0.061864635 | AO19: =(1+AO9)*(1+AO3)-1 -> 0.061864635 | AP19: =(1+AP9)*(1+AP3)-1 -> 0.061864635 | AQ19: =(1+AQ9)*(1+AQ3)-1 -> 0.061864635 | AR19: =(1+AR9)*(1+AR3)-1 -> 0.061864635 | AS19: =(1+AS9)*(1+AS3)-1 -> 0.061864635 | AT19: =(1+AT9)*(1+AT3)-1 -> 0.061864635 | AU19: =(1+AU9)*(1+AU3)-1 -> 0.061864635 | ... BG19: =(1+BG9)*(1+BG3)-1 -> 0.061864635
A20: Общие | D20: ЦМИ | F20: Ставка Euribor 3m | G20: % | I20: EoY, ЦМИ, 2022 и далее = 2021 | J20: 0.03294 | K20: 0.02865 | L20: 0.02124 | M20: 0.02155 | N20: 0.02488 | O20: 0.03725 | P20: 0.04684 | Q20: 0.02892 | R20: 0.007 | S20: 0.01006 | T20: 0.01356 | U20: 0.0049081058 | V20: 0.0015218502 | W20: 0.00078 | X20: -0.00131 | Y20: -0.00319 | Z20: -0.00329 | AA20: -0.00309 | AB20: -0.00383 | AC20: -0.00545 | AD20: -0.00572 | AE20: 0.02132 | AF20: 0.03909 | AG20: 0.02678 | AH20: 0.02026 | AI20: 0.0285 | AJ20: 0.0281 | AK20: 0.023 | AL20: 0.0228 | AM20: 0.0228 | AN20: =AM20 -> 0.0228 | AO20: =AN20 -> 0.0228 | AP20: =AO20 -> 0.0228 | AQ20: =AP20 -> 0.0228 | AR20: =AQ20 -> 0.0228 | AS20: =AR20 -> 0.0228 | AT20: =AS20 -> 0.0228 | AU20: =AT20 -> 0.0228 | ... BG20: =BF20 -> 0.0228
A21: Общие | D21: ЦМИ | F21: Процентный своп IRS 1Y Mosprime | G21: % | I21: EoY | O21: 0.0578 | P21: 0.0568 | Q21: 0.1575 | R21: 0.0732 | S21: 0.05335 | T21: 0.0721 | U21: 0.073222594 | V21: 0.069354529 | W21: 0.10586616 | X21: 0.116 | Y21: 0.10465 | Z21: 0.078 | AA21: 0.0957 | AB21: 0.0646 | AC21: 0.0504 | AD21: 0.1022 | AE21: 0.088 | AF21: 0.1516 | AG21: 0.2192 | AH21: 0.1515 | AI21: 0.13642095 | AJ21: 0.11417202 | AK21: 0.094298272 | AL21: 0.092975259 | AM21: 0.092975259 | AN21: =AM21+(AN$39-AM$39) -> 0.092975259 | AO21: =AN21+(AO$39-AN$39) -> 0.092975259 | AP21: =AO21+(AP$39-AO$39) -> 0.092975259 | AQ21: =AP21+(AQ$39-AP$39) -> 0.092975259 | AR21: =AQ21+(AR$39-AQ$39) -> 0.092975259 | AS21: =AR21+(AS$39-AR$39) -> 0.092975259 | AT21: =AS21+(AT$39-AS$39) -> 0.092975259 | AU21: =AT21+(AU$39-AT$39) -> 0.092975259 | ... BG21: =BF21+(BG$39-BF$39) -> 0.092975259
A22: Общие | D22: ЦМИ | F22: Процентный своп IRS 3Y Mosprime | G22: % | I22: EoY | O22: 0.0615 | P22: 0.0667 | Q22: 0.16 | R22: 0.076 | S22: 0.0675 | T22: 0.0742 | U22: 0.075070977 | V22: 0.069934962 | W22: 0.09891364 | X22: 0.1079 | Y22: 0.0953 | Z22: 0.0759 | AA22: 0.0968 | AB22: 0.0634 | AC22: 0.0554 | AD22: 0.0935 | AE22: 0.097 | AF22: 0.1293 | AG22: 0.1901 | AH22: 0.14 | AI22: 0.13311142 | AJ22: 0.10648377 | AK22: 0.095726654 | AL22: 0.095253555 | AM22: 0.095253891 | AN22: =AM22+(AN$39-AM$39) -> 0.095253891 | AO22: =AN22+(AO$39-AN$39) -> 0.095253891 | AP22: =AO22+(AP$39-AO$39) -> 0.095253891 | AQ22: =AP22+(AQ$39-AP$39) -> 0.095253891 | AR22: =AQ22+(AR$39-AQ$39) -> 0.095253891 | AS22: =AR22+(AS$39-AR$39) -> 0.095253891 | AT22: =AS22+(AT$39-AS$39) -> 0.095253891 | AU22: =AT22+(AU$39-AT$39) -> 0.095253891 | ... BG22: =BF22+(BG$39-BF$39) -> 0.095253891
A23: Общие | D23: ЦМИ | F23: Процентный своп IRS 5Y Mosprime | G23: % | I23: EoY | O23: 0.064 | P23: 0.0718 | Q23: 0.165 | R23: 0.0785 | S23: 0.0735 | T23: 0.0754 | U23: 0.076751556 | V23: 0.071434632 | W23: 0.096330785 | X23: 0.1062 | Y23: 0.0918 | Z23: 0.0755 | AA23: 0.0956 | AB23: 0.0646 | AC23: 0.0588 | AD23: 0.0894 | AE23: 0.102 | AF23: 0.124 | AG23: 0.1808 | AH23: 0.1395 | AI23: 0.13307039 | AJ23: 0.10666102 | AK23: 0.096383824 | AL23: 0.096079831 | AM23: 0.096080046 | AN23: =AM23+(AN$39-AM$39) -> 0.096080046 | AO23: =AN23+(AO$39-AN$39) -> 0.096080046 | AP23: =AO23+(AP$39-AO$39) -> 0.096080046 | AQ23: =AP23+(AQ$39-AP$39) -> 0.096080046 | AR23: =AQ23+(AR$39-AQ$39) -> 0.096080046 | AS23: =AR23+(AS$39-AR$39) -> 0.096080046 | AT23: =AS23+(AT$39-AS$39) -> 0.096080046 | AU23: =AT23+(AU$39-AT$39) -> 0.096080046 | ... BG23: =BF23+(BG$39-BF$39) -> 0.096080046
A24: Общие | D24: ЦМИ | F24: Процентный своп IRS 7Y Mosprime | G24: % | I24: EoY | O24: 0.0646 | P24: 0.0737 | Q24: 0.165 | R24: 0.0815 | S24: 0.07651 | T24: 0.0771 | U24: 0.078596912 | V24: 0.073566594 | W24: 0.095379851 | X24: 0.1054 | Y24: 0.0896 | Z24: 0.0753 | AA24: 0.0945 | AB24: 0.0682 | AC24: 0.0613 | AD24: 0.0879 | AE24: 0.1048 | AF24: 0.12216 | AG24: =AG23+(AG25-AG23)*2/5 -> 0.17244 | AH24: =AH23+(AH25-AH23)*2/5 -> 0.1405 | AI24: =AI23+(AI25-AI23)*2/5 -> 0.14260223 | AJ24: =AJ23+(AJ25-AJ23)*2/5 -> 0.11559661 | AK24: =AK23+(AK25-AK23)*2/5 -> 0.097408956 | AL24: =AL23+(AL25-AL23)*2/5 -> 0.097156651 | AM24: =AM23+(AM25-AM23)*2/5 -> 0.097156938 | AN24: =AN23+(AN25-AN23)*2/5 -> 0.097156938 | ... BG24: =BG23+(BG25-BG23)*2/5 -> 0.097156938
A25: Общие | D25: ЦМИ | F25: Процентный своп IRS 10Y Mosprime | G25: % | I25: EoY | O25: 0.0651 | P25: 0.0766 | Q25: 0.165 | R25: 0.082 | S25: 0.07951 | T25: 0.0789 | U25: 0.081269617 | V25: 0.076304414 | W25: 0.095675602 | X25: 0.1039 | Y25: 0.0873 | Z25: 0.0753 | AA25: 0.0932 | AB25: 0.0684 | AC25: 0.0646 | AD25: 0.0877 | AE25: 0.109 | AF25: 0.1194 | AG25: 0.1599 | AH25: 0.142 | AI25: 0.1569 | AJ25: 0.129 | AK25: 0.098946654 | AL25: 0.098771881 | AM25: 0.098772277 | AN25: =AM25+(AN$39-AM$39) -> 0.098772277 | AO25: =AN25+(AO$39-AN$39) -> 0.098772277 | AP25: =AO25+(AP$39-AO$39) -> 0.098772277 | AQ25: =AP25+(AQ$39-AP$39) -> 0.098772277 | AR25: =AQ25+(AR$39-AQ$39) -> 0.098772277 | AS25: =AR25+(AS$39-AR$39) -> 0.098772277 | AT25: =AS25+(AT$39-AS$39) -> 0.098772277 | AU25: =AT25+(AU$39-AT$39) -> 0.098772277 | ... BG25: =BF25+(BG$39-BF$39) -> 0.098772277
A26: Общие | D26: Расчет | F26: Средний за период курс рубля к CHF (av CHF/RUB) | G26: CHF/руб | I26: формула | J26: 17.318563 | K26: 20.225352 | L26: 22.797648 | M26: 23.200051 | N26: 22.726587 | O26: 21.674498 | P26: 21.310417 | Q26: 22.92536 | R26: 29.245194 | S26: 29.492689 | T26: 33.218057 | U26: 33.114757 | V26: 34.428351 | W26: 42.014608 | X26: 63.877109 | Y26: 67.848924 | Z26: 59.296313 | AA26: 64.271353 | AB26: 65.038546 | AC26: 77.342137 | AD26: 80.517746 | AE26: 74.698218 | AF26: 93.350656 | AG26: 105.25576 | AH26: 100.28323 | AI26: =AI14/AI41 -> 97.05608 | AJ26: =AJ14/AJ41 -> 110.00149 | AK26: =AK14/AK41 -> 115.01449 | AL26: =AL14/AL41 -> 119.93299 | AM26: =AM14/AM41 -> 125.06799 | AN26: =AN14/AN41 -> 127.56935 | AO26: =AO14/AO41 -> 130.12074 | AP26: =AP14/AP41 -> 132.72316 | ... BG26: =BG14/BG41 -> 185.84446
A27: Общие | D27: Расчет | F27: Курс рубля к CHF в конце года (eop CHF/RUB) | G27: CHF/руб | I27: формула | J27: 17.86 | K27: 22.778 | L27: 23.5995 | M27: 24.4827 | N27: 21.9563 | O27: 21.597 | P27: 21.7879 | Q27: 27.8329 | R27: 29.137 | S27: 32.4084 | T27: 34.2366 | U27: 33.2888 | V27: 36.696 | W27: 56.9763 | X27: 73.611527 | Y27: 59.4151 | Z27: 58.9743 | AA27: 70.5787 | AB27: 63.6039 | AC27: 83.5131 | AD27: 80.9376 | AE27: 76.1805 | AF27: 106.7591 | AG27: 112.9774 | AH27: 99.1969 | AI27: =AI7/AI40 -> 110.94649 | AJ27: =AJ7/AJ40 -> 112.21018 | AK27: =AK7/AK40 -> 117.03069 | AL27: =AL7/AL40 -> 122.03675 | AM27: =AM7/AM40 -> 127.26401 | AN27: =AN7/AN40 -> 127.56935 | AO27: =AO7/AO40 -> 130.12074 | AP27: =AP7/AP40 -> 132.72316 | ... BG27: =BG7/BG40 -> 185.84446
A28: Общие | D28: CIB Research | F28: Инфляция - Рост индекса цен производителей в США, в долларах США (USD, eop PPI) | G28: % | I28: =CPI | J28: -0.016 | K28: 0.012 | L28: 0.04 | M28: 0.042 | N28: 0.054 | O28: 0.011 | P28: 0.062 | Q28: -0.009 | R28: 0.043 | S28: 0.038 | T28: 0.047 | U28: 0.021 | V28: 0.004 | W28: 0.008 | X28: -0.051 | Y28: -0.019 | Z28: 0.032 | AA28: 0.013 | AB28: 0.017 | AC28: -0.008 | AD28: 0.122 | AE28: 0.064115004 | AF28: 0.03323156 | AG28: =AG4 -> 0.028723677 | AH28: =AH4 -> 0.026899449 | AI28: =AI4 -> 0.027326387 | AJ28: =AJ4 -> 0.026069089 | AK28: =AK4 -> 0.022921913 | AL28: =AL4 -> 0.01939121 | AM28: =AM4 -> 0.02235396 | AN28: =AN4 -> 0.02 | ... BG28: =BG4 -> 0.02
A29: Общие | D29: CIB Research | F29: Инфляция - Рост индекса потребительских цен в Еврозоне (EUR, eop CPI) | G29: % | I29: EoY HICP, source: FX/IR team | J29: 0.021 | K29: 0.023 | L29: 0.02 | M29: 0.023 | N29: 0.023 | O29: 0.019 | P29: 0.031 | Q29: 0.016 | R29: 0.009 | S29: 0.022 | T29: 0.028 | U29: 0.022212505 | V29: 0.0084695012 | W29: -0.002 | X29: 0.0044947037 | Y29: 0.011242984 | Z29: 0.01357189 | AA29: 0.015592772 | AB29: 0.013479362 | AC29: -0.0026189844 | AD29: 0.050069593 | AE29: 0.092074037 | AF29: 0.029353964 | AG29: 0.024563883 | AH29: 0.019664407 | AI29: 0.029057119 | AJ29: 0.019429195 | AK29: 0.023805054 | AL29: 0.018896804 | AM29: 0.021378704 | AN29: 0.02 | AO29: =AN29 -> 0.02 | AP29: =AO29 -> 0.02 | AQ29: =AP29 -> 0.02 | AR29: =AQ29 -> 0.02 | AS29: =AR29 -> 0.02 | AT29: =AS29 -> 0.02 | AU29: =AT29 -> 0.02 | AV29: =AU29 -> 0.02 | ... BG29: =BF29 -> 0.02
A30: Общие | D30: CIB Research | F30: Инфляция - Рост индекса цен производителей в Еврозоне (EUR, eop PPI) | G30: % | I30: =CPI | J30: -0.005 | K30: 0.015 | L30: 0.01 | M30: 0.037 | N30: 0.045 | O30: 0.038 | P30: 0.044 | Q30: 0.015 | R30: -0.03 | S30: 0.05 | T30: 0.044 | U30: 0.024 | V30: -0.001 | W30: -0.013 | X30: -0.019 | Y30: -0.011 | Z30: 0.022 | AA30: 0.031 | AB30: -0.007 | AC30: -0.011 | AD30: 0.237 | AE30: 0.092074037 | AF30: 0.029353964 | AG30: =AG29 -> 0.024563883 | AH30: =AH29 -> 0.019664407 | AI30: =AI29 -> 0.029057119 | AJ30: =AJ29 -> 0.019429195 | AK30: =AK29 -> 0.023805054 | AL30: =AL29 -> 0.018896804 | AM30: =AM29 -> 0.021378704 | AN30: =AN29 -> 0.02 | ... BG30: =BG29 -> 0.02
A31: Общие | D31: Законодательство | F31: Ставка страхового взноса в ФОМС | G31: % | I31: Не меняется | U31: 0.051 | V31: 0.051 | W31: 0.051 | X31: 0.051 | Y31: 0.051 | Z31: 0.051 | AA31: 0.051 | AB31: 0.051 | AC31: 0.051 | AD31: 0.051 | AE31: 0.051 | AF31: 0.051 | AG31: =AF31 -> 0.051 | AH31: =AG31 -> 0.051 | AI31: =AH31 -> 0.051 | AJ31: =AI31 -> 0.051 | AK31: =AJ31 -> 0.051 | AL31: =AK31 -> 0.051 | AM31: =AL31 -> 0.051 | AN31: =AM31 -> 0.051 | ... BG31: =BF31 -> 0.051
A32: Общие | D32: Законодательство | F32: Ставка страхового взноса в ФСС | G32: % | I32: Не меняется | U32: 0.029 | V32: 0.029 | W32: 0.029 | X32: 0.029 | Y32: 0.029 | Z32: 0.029 | AA32: 0.029 | AB32: 0.029 | AC32: 0.029 | AD32: 0.029 | AE32: 0.029 | AF32: 0.029 | AG32: =AF32 -> 0.029 | AH32: =AG32 -> 0.029 | AI32: =AH32 -> 0.029 | AJ32: =AI32 -> 0.029 | AK32: =AJ32 -> 0.029 | AL32: =AK32 -> 0.029 | AM32: =AL32 -> 0.029 | AN32: =AM32 -> 0.029 | ... BG32: =BF32 -> 0.029
A33: Общие | D33: Законодательство | F33: Ставка страхового взноса в ПФР | G33: % | I33: Не меняется | U33: 0.22 | V33: 0.22 | W33: 0.22 | X33: 0.22 | Y33: 0.22 | Z33: 0.22 | AA33: 0.22 | AB33: 0.22 | AC33: 0.22 | AD33: 0.22 | AE33: 0.22 | AF33: 0.22 | AG33: =AF33 -> 0.22 | AH33: =AG33 -> 0.22 | AI33: =AH33 -> 0.22 | AJ33: =AI33 -> 0.22 | AK33: =AJ33 -> 0.22 | AL33: =AK33 -> 0.22 | AM33: =AL33 -> 0.22 | AN33: =AM33 -> 0.22 | ... BG33: =BF33 -> 0.22
A34: Общие | D34: Законодательство | F34: Ставка налога на прибыль организаций | G34: % | I34: Не меняется | U34: 0.2 | V34: 0.2 | W34: 0.2 | X34: 0.2 | Y34: 0.2 | Z34: 0.2 | AA34: 0.2 | AB34: 0.2 | AC34: 0.2 | AD34: 0.2 | AE34: 0.2 | AF34: 0.2 | AG34: =AF34 -> 0.2 | AH34: 0.25 | AI34: =AH34 -> 0.25 | AJ34: =AI34 -> 0.25 | AK34: =AJ34 -> 0.25 | AL34: =AK34 -> 0.25 | AM34: =AL34 -> 0.25 | AN34: =AM34 -> 0.25 | AO34: =AN34 -> 0.25 | AP34: =AO34 -> 0.25 | ... BG34: =BF34 -> 0.25
A35: Общие | D35: ЦМИ | F35: Средний за период курс EUR к доллару США (av EUR/USD) | G35: EUR/$ | I35: 2017-21 ЦМИ | J35: 0.8956 | K35: 0.9456 | L35: 1.1312 | M35: 1.2439 | N35: 1.2441 | O35: 1.2556 | P35: 1.3705 | Q35: 1.4708 | R35: 1.3948 | S35: 1.3257 | T35: 1.392 | W35: 1.32 | X35: 1.1098449 | Y35: 1.1075317 | Z35: 1.1301778 | AA35: 1.1806945 | AB35: 1.1073 | AC35: 1.1411541 | AD35: 1.183766 | AE35: 1.0518288 | AF35: 1.0820174 | AG35: 1.0830867 | AH35: 1.1306638 | AI35: 1.1629283 | AJ35: 1.1539085 | AK35: 1.1496253 | AL35: 1.1501243 | AM35: 1.1498759 | AN35: =AM35 -> 1.1498759 | AO35: =AN35 -> 1.1498759 | AP35: =AO35 -> 1.1498759 | AQ35: =AP35 -> 1.1498759 | AR35: =AQ35 -> 1.1498759 | AS35: =AR35 -> 1.1498759 | AT35: =AS35 -> 1.1498759 | AU35: =AT35 -> 1.1498759 | ... BG35: =BF35 -> 1.1498759
A36: Общие | D36: Расчет | F36: Курс EUR к доллару США в конце года (eop EUR/USD) | G36: EUR/$ | J36: 0.8813 | K36: 1.0487 | L36: 1.263 | M36: 1.3621 | N36: 1.1797 | O36: 1.317 | P36: 1.4721 | Q36: 1.3917 | R36: 1.4406 | S36: 1.3362 | T36: 1.2939 | U36: 1.3194 | V36: 1.3791 | W36: 1.2141 | X36: 1.08655 | Y36: 1.0516 | Z36: 1.1994 | AA36: 1.1456 | AB36: 1.1214 | AC36: 1.2217 | AD36: 1.137 | AE36: 1.0702 | AF36: 1.1036 | AG36: 1.0434697 | AH36: 1.1772681 | AI36: 1.16 | AJ36: 1.15 | AK36: 1.15 | AL36: 1.15 | AM36: 1.15 | AN36: =AN35 -> 1.1498759 | AO36: =AO35 -> 1.1498759 | AP36: =AP35 -> 1.1498759 | AQ36: =AQ35 -> 1.1498759 | AR36: =AR35 -> 1.1498759 | AS36: =AS35 -> 1.1498759 | AT36: =AT35 -> 1.1498759 | AU36: =AU35 -> 1.1498759 | ... BG36: =BG35 -> 1.1498759
A37: Общие | D37: ЦМИ | F37: ECB policy rate (Main Refinancing Operations rate) | G37: % | I37: EoY, ЦМИ, 2022 и далее = 2021 | J37: 0.0325 | K37: 0.0275 | L37: 0.02 | M37: 0.02 | N37: 0.0225 | O37: 0.035 | P37: 0.04 | Q37: 0.025 | R37: 0.01 | S37: 0.01 | T37: 0.01 | U37: 0.0075 | V37: 0.0025 | W37: 0.0005 | X37: 0.0005 | Y37: 0 | Z37: 0 | AA37: 0 | AB37: 0 | AC37: 0 | AD37: 0 | AE37: 0.025 | AF37: 0.045 | AG37: 0.0315 | AH37: 0.0215 | AI37: 0.0265 | AJ37: 0.024 | AK37: 0.0215 | AL37: 0.0215 | AM37: 0.0215 | AN37: =AM37 -> 0.0215 | AO37: =AN37 -> 0.0215 | AP37: =AO37 -> 0.0215 | AQ37: =AP37 -> 0.0215 | AR37: =AQ37 -> 0.0215 | AS37: =AR37 -> 0.0215 | AT37: =AS37 -> 0.0215 | AU37: =AT37 -> 0.0215 | ... BG37: =BF37 -> 0.0215
A38: Общие | D38: Расчет | F38: Курс EUR к CHF в конце года (eop EUR/CHF) | G38: EUR/CHF | I38: формула | J38: 1.4777 | K38: 1.4514 | L38: 1.56045 | M38: 1.546 | N38: 1.55615 | O38: 1.6091 | P38: 1.6536 | Q38: 1.49358 | R38: 1.48365 | S38: 1.25161 | T38: 1.21689 | U38: 1.2072 | V38: 1.2276 | W38: 1.2024 | X38: 1.0887316 | Y38: 1.074 | Z38: 1.17 | AA38: 1.127 | AB38: 1.0854 | AC38: 1.0809642 | AD38: 1.0373444 | AE38: 0.9893 | AF38: 0.9287 | AG38: 0.9392 | AH38: 0.9311 | AI38: =AI36*AI40 -> 0.920576 | AJ38: =AJ36*AJ40 -> 0.95519 | AK38: =AK36*AK40 -> 0.95519 | AL38: =AL36*AL40 -> 0.95519 | AM38: =AM36*AM40 -> 0.95519 | AN38: =AN36*AN40 -> 0.95508695 | AO38: =AO36*AO40 -> 0.95508695 | AP38: =AP36*AP40 -> 0.95508695 | ... BG38: =BG36*BG40 -> 0.95508695
A39: Общие | D39: ЦМИ | F39: Ключевая ставка на конец года (eop) | G39: % | I39: С 2021 года = инфляция + 2% | T39: 0.0525 | W39: 0.17 | X39: 0.11 | Y39: 0.1 | Z39: 0.0775 | AA39: 0.0775 | AB39: 0.0625 | AC39: 0.0425 | AD39: 0.085 | AE39: 0.075 | AF39: 0.16 | AG39: 0.21 | AH39: 0.16 | AI39: 0.1375 | AJ39: 0.12 | AK39: 0.095 | AL39: 0.09 | AM39: 0.09 | AN39: =AM39 -> 0.09 | AO39: =AN39 -> 0.09 | AP39: =AO39 -> 0.09 | AQ39: =AP39 -> 0.09 | AR39: =AQ39 -> 0.09 | AS39: =AR39 -> 0.09 | AT39: =AS39 -> 0.09 | AU39: =AT39 -> 0.09 | ... BG39: =BF39 -> 0.09
A40: Общие | D40: Расчет | F40: USD/CHF eop | G40: USD/CHF | J40: 1.6603 | K40: 1.3836 | L40: 1.2391 | M40: 1.1404 | N40: 1.3134 | O40: 1.2201 | P40: 1.1335 | Q40: 1.0687 | R40: 1.0352 | S40: 0.9352 | T40: 0.9381 | X40: 1.01 | Y40: 1.016 | Z40: 0.974 | AA40: 0.983 | AB40: 0.9676 | AC40: 0.8852 | AD40: 0.9129 | AE40: 0.9244 | AF40: 0.8415 | AG40: 0.9072 | AH40: =AI41 -> 0.8306 | AI40: 0.7936 | AJ40: =AK41 -> 0.8306 | AK40: =AL41 -> 0.8306 | AL40: =AM41 -> 0.8306 | AM40: =AM41 -> 0.8306 | AN40: =AO41 -> 0.8306 | AO40: =AP41 -> 0.8306 | AP40: =AQ41 -> 0.8306 | AQ40: =AR41 -> 0.8306 | AR40: =AS41 -> 0.8306 | AS40: =AT41 -> 0.8306 | AT40: =AU41 -> 0.8306 | AU40: =AV41 -> 0.8306 | ... BA40: =BB41 -> 0.8306 | BB40: =BB41 -> 0.8306 | BC40: =BC41 -> 0.8306 | BD40: =BD41 -> 0.8306 | BE40: =BE41 -> 0.8306 | BF40: =BF41 -> 0.8306 | BG40: =BG41 -> 0.8306
...

Sheet Inputs Q LTM
A1: INPUTS | B1: Отрасль | C1: Подотрасль/ Дивизион | D1: Источник | E1: Дата обновления | F1: Наименование | G1: Ед. измерения | H1: Link | I1: Комментарий к заполнению (формула) | J1: 2001 Q1 | K1: 2001 Q2 | L1: 2001 Q3 | M1: 2001 Q4 | N1: 2002 Q1 | O1: 2002 Q2 | P1: 2002 Q3 | Q1: 2002 Q4 | R1: 2003 Q1 | S1: 2003 Q2 | T1: 2003 Q3 | U1: 2003 Q4 | V1: 2004 Q1 | W1: 2004 Q2 | X1: 2004 Q3 | Y1: 2004 Q4 | Z1: 2005 Q1 | AA1: 2005 Q2 | AB1: 2005 Q3 | AC1: 2005 Q4 | AD1: 2006 Q1 | AE1: 2006 Q2 | AF1: 2006 Q3 | AG1: 2006 Q4 | AH1: 2007 Q1 | AI1: 2007 Q2 | AJ1: 2007 Q3 | AK1: 2007 Q4 | AL1: 2008 Q1 | AM1: 2008 Q2 | AN1: 2008 Q3 | AO1: 2008 Q4 | AP1: 2009 Q1 | AQ1: 2009 Q2 | AR1: 2009 Q3 | AS1: 2009 Q4 | AT1: 2010 Q1 | AU1: 2010 Q2 | AV1: 2010 Q3 | AW1: 2010 Q4 | AX1: 2011 Q1 | AY1: 2011 Q2 | AZ1: 2011 Q3 | BA1: 2011 Q4 | BB1: 2012 Q1 | BC1: 2012 Q2 | BD1: 2012 Q3 | BE1: 2012 Q4 | BF1: 2013 Q1 | BG1: 2013 Q2 | BH1: 2013 Q3 | BI1: 2013 Q4 | BJ1: 2014 Q1 | BK1: 2014 Q2 | BL1: 2014 Q3 | BM1: 2014 Q4 | BN1: 2015 Q1 | BO1: 2015 Q2 | BP1: 2015 Q3 | BQ1: 2015 Q4 | BR1: 2016 Q1 | BS1: 2016 Q2 | BT1: 2016 Q3 | BU1: 2016 Q4 | BV1: 2017 Q1 | BW1: 2017 Q2 | BX1: 2017 Q3 | BY1: 2017 Q4 | BZ1: 2018 Q1 | CA1: 2018 Q2 | CB1: 2018 Q3 | CC1: 2018 Q4 | CD1: 2019 Q1 | CE1: 2019 Q2 | CF1: 2019 Q3 | CG1: 2019 Q4 | CH1: 2020 Q1 | CI1: 2020 Q2 | CJ1: 2020 Q3 | CK1: 2020 Q4 | CL1: 2021 Q1 | CM1: 2021 Q2 | CN1: 2021 Q3 | CO1: 2021 Q4 | CP1: 2022 Q1 | CQ1: 2022 Q2 | CR1: 2022 Q3 | CS1: 2022 Q4 | CT1: 2023 Q1 | CU1: 2023 Q2 | CV1: 2023 Q3 | CW1: 2023 Q4 | CX1: 2024 Q1 | CY1: 2024 Q2 | CZ1: 2024 Q3 | DA1: 2024 Q4 | DB1: 2025 Q1 | DC1: 2025 Q2 | DD1: 2025 Q3 | DE1: 2025 Q4 | DF1: 2026 Q1 | DG1: 2026 Q2 | DH1: 2026 Q3 | DI1: 2026 Q4 | DJ1: 2027 Q1 | DK1: 2027 Q2 | DL1: 2027 Q3 | DM1: 2027 Q4 | DN1: 2028 Q1 | DO1: 2028 Q2 | DP1: 2028 Q3 | DQ1: 2028 Q4 | DR1: 2029 Q1 | DS1: 2029 Q2 | DT1: 2029 Q3 | DU1: 2029 Q4 | DV1: 2030 Q1 | DW1: 2030 Q2 | DX1: 2030 Q3 | DY1: 2030 Q4 | DZ1: 2031 Q1 | EA1: 2031 Q2 | EB1: 2031 Q3 | EC1: 2031 Q4 | ED1: 2032 Q1 | EE1: 2032 Q2 | EF1: 2032 Q3 | EG1: 2032 Q4 | EH1: 2033 Q1 | EI1: 2033 Q2 | EJ1: 2033 Q3 | EK1: 2033 Q4 | EL1: 2034 Q1 | EM1: 2034 Q2 | EN1: 2034 Q3 | EO1: 2034 Q4 | EP1: 2035 Q1 | EQ1: 2035 Q2 | ER1: 2035 Q3 | ES1: 2035 Q4 | ET1: 2036 Q1 | EU1: 2036 Q2 | EV1: 2036 Q3 | EW1: 2036 Q4 | EX1: 2037 Q1 | EY1: 2037 Q2 | EZ1: 2037 Q3 | FA1: 2037 Q4 | FB1: 2038 Q1 | FC1: 2038 Q2 | FD1: 2038 Q3 | FE1: 2038 Q4 | FF1: 2039 Q1 | FG1: 2039 Q2 | FH1: 2039 Q3 | FI1: 2039 Q4 | FJ1: 2040 Q1 | FK1: 2040 Q2 | FL1: 2040 Q3 | FM1: 2040 Q4 | FN1: 2041 Q1 | FO1: 2041 Q2 | FP1: 2041 Q3 | FQ1: 2041 Q4 | FR1: 2042 Q1 | FS1: 2042 Q2 | FT1: 2042 Q3 | FU1: 2042 Q4 | FV1: 2043 Q1 | FW1: 2043 Q2 | FX1: 2043 Q3 | FY1: 2043 Q4 | FZ1: 2044 Q1 | GA1: 2044 Q2 | GB1: 2044 Q3 | GC1: 2044 Q4 | GD1: 2045 Q1 | GE1: 2045 Q2 | GF1: 2045 Q3 | GG1: 2045 Q4 | GH1: 2046 Q1 | GI1: 2046 Q2 | GJ1: 2046 Q3 | GK1: 2046 Q4 | GL1: 2047 Q1 | GM1: 2047 Q2 | GN1: 2047 Q3 | GO1: 2047 Q4 | GP1: 2048 Q1 | GQ1: 2048 Q2 | GR1: 2048 Q3 | GS1: 2048 Q4 | GT1: 2049 Q1 | GU1: 2049 Q2 | GV1: 2049 Q3 | GW1: 2049 Q4 | GX1: 2050 Q1 | GY1: 2050 Q2 | GZ1: 2050 Q3 | HA1: 2050 Q4
A2: Общие | D2: ЦМИ | F2: Рост реального ВВП | G2: % | H2: Наименование листа, номер строки [например: Scenarios, line 352] | I2: =Inputs!I2 -> Базовый 11.09.2026 | J2: 0.047 | K2: 0.051 | L2: 0.06 | M2: 0.045 | N2: 0.038 | O2: 0.044 | P2: 0.044 | Q2: 0.062 | R2: 0.076 | S2: 0.08 | T2: 0.062 | U2: 0.077 | V2: 0.072 | W2: 0.08 | X2: 0.073 | Y2: 0.062 | Z2: 0.056 | AA2: 0.06 | AB2: 0.06 | AC2: 0.078 | AD2: 0.073 | AE2: 0.081 | AF2: 0.082 | AG2: 0.089 | AH2: 0.081 | AI2: 0.086 | AJ2: 0.082 | AK2: 0.092 | AL2: 0.092 | AM2: 0.079 | AN2: 0.064 | AO2: -0.013 | AP2: -0.092 | AQ2: -0.112 | AR2: -0.086 | AS2: -0.026 | AT2: 0.041 | AU2: 0.05 | AV2: 0.038 | AW2: 0.051 | AX2: 0.033 | AY2: 0.033 | AZ2: 0.05 | BA2: 0.052 | BB2: 0.054 | BC2: 0.044 | BD2: 0.033 | BE2: 0.019 | BF2: 0.013 | BG2: 0.017 | BH2: 0.016 | BI2: 0.025 | BJ2: 0.005 | BK2: 0.013 | BL2: 0.009 | BM2: 0.003 | BN2: -0.018 | BO2: -0.035 | BP2: -0.02 | BQ2: -0.019 | BR2: -0.004 | BS2: 0.003 | BT2: 0.003 | BU2: 0.01 | BV2: 0.015 | BW2: 0.025 | BX2: 0.023 | BY2: 0.003 | BZ2: 0.025631888 | CA2: 0.027290417 | CB2: 0.02633714 | CC2: 0.032389366 | CD2: 0.013884401 | CE2: 0.013573986 | CF2: 0.027674168 | CG2: 0.03069449 | CH2: 0.015160754 | CI2: -0.073154521 | CJ2: -0.033281492 | CK2: -0.01301204 | CL2: 0.0086873079 | CM2: 0.11365971 | CN2: 0.052215697 | CO2: 0.060835967 | CP2: 0.033757193 | CQ2: -0.03703181 | CR2: -0.029390265 | CS2: -0.019173764 | CT2: -0.0083084244 | CU2: 0.053442387 | CV2: 0.06146633 | CW2: 0.051925939 | CX2: 0.058907601 | CY2: 0.048963808 | CZ2: 0.037934539 | DA2: 0.052090712 | DB2: 0.013093854 | DC2: 0.010385269 | DD2: 0.0075002464 | DE2: 0.0095134385 | DF2: -0.0015161431 | DG2: 0.013 | DH2: 0.0065734477 | DI2: 0.006594219 | DJ2: 0.017387688 | DK2: 0.0093453298 | DL2: 0.014243555 | DM2: 0.014751328 | DN2: =Inputs!AK2 -> 0.0163 | DO2: =Inputs!AK2 -> 0.0163 | DP2: =Inputs!AK2 -> 0.0163 | DQ2: =Inputs!AK2 -> 0.0163 | DR2: =Inputs!AL2 -> 0.0182 | DS2: =Inputs!AL2 -> 0.0182 | DT2: =Inputs!AL2 -> 0.0182 | DU2: =Inputs!AL2 -> 0.0182 | DV2: =Inputs!AM2 -> 0.0182 | DW2: =Inputs!AM2 -> 0.0182 | DX2: =Inputs!AM2 -> 0.0182 | DY2: =Inputs!AM2 -> 0.0182 | DZ2: =Inputs!AN2 -> 0.0182 | EA2: =Inputs!AN2 -> 0.0182 | EB2: =Inputs!AN2 -> 0.0182 | EC2: =Inputs!AN2 -> 0.0182 | ED2: =Inputs!AO2 -> 0.0182 | EE2: =Inputs!AO2 -> 0.0182 | EF2: =Inputs!AO2 -> 0.0182 | EG2: =Inputs!AO2 -> 0.0182 | EH2: =Inputs!AP2 -> 0.0182 | EI2: =Inputs!AP2 -> 0.0182 | EJ2: =Inputs!AP2 -> 0.0182 | EK2: =Inputs!AP2 -> 0.0182 | EL2: =Inputs!AQ2 -> 0.0182 | EM2: =Inputs!AP2 -> 0.0182 | EN2: =Inputs!AQ2 -> 0.0182 | EO2: =Inputs!AQ2 -> 0.0182 | EP2: =Inputs!AR2 -> 0.0182 | EQ2: =Inputs!AR2 -> 0.0182 | ER2: =Inputs!AR2 -> 0.0182 | ES2: =Inputs!AR2 -> 0.0182 | ET2: =Inputs!AS2 -> 0.0182 | EU2: =Inputs!AS2 -> 0.0182 | EV2: =Inputs!AS2 -> 0.0182 | EW2: =Inputs!AS2 -> 0.0182 | EX2: =Inputs!AT2 -> 0.0182 | EY2: =Inputs!AT2 -> 0.0182 | EZ2: =Inputs!AT2 -> 0.0182 | FA2: =Inputs!AT2 -> 0.0182 | FB2: =Inputs!AU2 -> 0.0182 | FC2: =Inputs!AU2 -> 0.0182 | FD2: =Inputs!AU2 -> 0.0182 | FE2: =Inputs!AU2 -> 0.0182 | FF2: =Inputs!AV2 -> 0.0182 | FG2: =Inputs!AV2 -> 0.0182 | FH2: =Inputs!AV2 -> 0.0182 | FI2: =Inputs!AV2 -> 0.0182 | FJ2: =Inputs!AW2 -> 0.0182 | FK2: =Inputs!AW2 -> 0.0182 | FL2: =Inputs!AW2 -> 0.0182 | FM2: =Inputs!AW2 -> 0.0182 | FN2: =Inputs!AX2 -> 0.0182 | FO2: =Inputs!AX2 -> 0.0182 | FP2: =Inputs!AX2 -> 0.0182 | FQ2: =Inputs!AX2 -> 0.0182 | FR2: =Inputs!AY2 -> 0.0182 | FS2: =Inputs!AY2 -> 0.0182 | FT2: =Inputs!AY2 -> 0.0182 | FU2: =Inputs!AY2 -> 0.0182 | FV2: =Inputs!AZ2 -> 0.0182 | FW2: =Inputs!AZ2 -> 0.0182 | FX2: =Inputs!AZ2 -> 0.0182 | FY2: =Inputs!AZ2 -> 0.0182 | FZ2: =Inputs!BA2 -> 0.0182 | GA2: =Inputs!BA2 -> 0.0182 | GB2: =Inputs!BA2 -> 0.0182 | GC2: =Inputs!BA2 -> 0.0182 | GD2: =Inputs!BB2 -> 0.0182 | GE2: =Inputs!BB2 -> 0.0182 | GF2: =Inputs!BB2 -> 0.0182 | GG2: =Inputs!BB2 -> 0.0182 | GH2: =Inputs!BC2 -> 0.0182 | GI2: =Inputs!BC2 -> 0.0182 | GJ2: =Inputs!BC2 -> 0.0182 | GK2: =Inputs!BC2 -> 0.0182 | GL2: =Inputs!BD2 -> 0.0182 | GM2: =Inputs!BD2 -> 0.0182 | GN2: =Inputs!BD2 -> 0.0182 | GO2: =Inputs!BD2 -> 0.0182 | GP2: =Inputs!BE2 -> 0.0182 | GQ2: =Inputs!BE2 -> 0.0182 | GR2: =Inputs!BE2 -> 0.0182 | GS2: =Inputs!BE2 -> 0.0182 | GT2: =Inputs!BF2 -> 0.0182 | GU2: =Inputs!BF2 -> 0.0182 | GV2: =Inputs!BF2 -> 0.0182 | GW2: =Inputs!BF2 -> 0.0182 | GX2: =Inputs!BG2 -> 0.0182 | GY2: =Inputs!BG2 -> 0.0182 | GZ2: =Inputs!BG2 -> 0.0182 | HA2: =Inputs!BG2 -> 0.0182
A3: Общие | D3: ЦМИ | F3: Инфляция - Рост индекса потребительских цен (RUB, eop CPI) | G3: % | I3: С 2021 года прогноз CIB | J3: 0.237 | K3: 0.237 | L3: 0.2 | M3: 0.186 | N3: 0.168 | O3: 0.147 | P3: 0.149 | Q3: 0.151 | R3: 0.148 | S3: 0.139 | T3: 0.133 | U3: 0.12 | V3: 0.103 | W3: 0.101 | X3: 0.114 | Y3: 0.117 | Z3: 0.136 | AA3: 0.137 | AB3: 0.123 | AC3: 0.109 | AD3: 0.106 | AE3: 0.09 | AF3: 0.095 | AG3: 0.09 | AH3: 0.074 | AI3: 0.085 | AJ3: 0.094 | AK3: 0.119 | AL3: 0.133 | AM3: 0.151 | AN3: 0.15 | AO3: 0.133 | AP3: 0.14 | AQ3: 0.119 | AR3: 0.107 | AS3: 0.088 | AT3: 0.065 | AU3: 0.058 | AV3: 0.07 | AW3: 0.088 | AX3: 0.095 | AY3: 0.094 | AZ3: 0.072 | BA3: 0.061 | BB3: 0.037 | BC3: 0.043 | BD3: 0.066 | BE3: 0.066 | BF3: 0.07 | BG3: 0.069 | BH3: 0.061 | BI3: 0.065 | BJ3: 0.0692 | BK3: 0.0781 | BL3: 0.0803 | BM3: 0.1135 | BN3: 0.1692 | BO3: 0.1528 | BP3: 0.1568 | BQ3: 0.1291 | BR3: 0.0727 | BS3: 0.0749 | BT3: 0.0643 | BU3: 0.0539 | BV3: 0.0425 | BW3: 0.0435 | BX3: 0.0296 | BY3: 0.0251 | BZ3: 0.0235 | CA3: 0.0229 | CB3: 0.0338 | CC3: 0.0426 | CD3: 0.0525 | CE3: 0.0466 | CF3: 0.0399 | CG3: 0.0304 | CH3: 0.0254 | CI3: 0.0321 | CJ3: 0.0367 | CK3: 0.0491 | CL3: 0.057820226 | CM3: 0.065115255 | CN3: 0.074080861 | CO3: 0.083930153 | CP3: 0.16695122 | CQ3: 0.1589738 | CR3: 0.13670964 | CS3: 0.11922836 | CT3: 0.0351 | CU3: 0.0325 | CV3: 0.06 | CW3: 0.0742 | CX3: 0.0772 | CY3: 0.0859 | CZ3: 0.0863 | DA3: 0.0952 | DB3: 0.1034 | DC3: 0.094 | DD3: 0.0798 | DE3: 0.0559 | DF3: 0.0586 | DG3: 0.0602 | DH3: 0.063349529 | DI3: 0.067380961 | DJ3: 0.05401422 | DK3: 0.051249764 | DL3: 0.049133784 | DM3: 0.047439689 | DN3: 0.043389563 | DO3: 0.047072709 | DP3: 0.042124625 | DQ3: 0.040050205 | DR3: 0.040469247 | DS3: 0.040469043 | DT3: 0.039847139 | DU3: 0.039847139 | DV3: 0.03995079 | DW3: 0.03995079 | DX3: 0.03995079 | DY3: 0.03995079 | DZ3: =Inputs!AN3 -> 0.04 | EA3: =Inputs!AN3 -> 0.04 | EB3: =Inputs!AN3 -> 0.04 | EC3: =Inputs!AN3 -> 0.04 | ED3: =Inputs!AO3 -> 0.04 | EE3: =Inputs!AO3 -> 0.04 | EF3: =Inputs!AO3 -> 0.04 | EG3: =Inputs!AO3 -> 0.04 | EH3: =Inputs!AP3 -> 0.04 | EI3: =Inputs!AP3 -> 0.04 | EJ3: =Inputs!AP3 -> 0.04 | EK3: =Inputs!AP3 -> 0.04 | EL3: =Inputs!AQ3 -> 0.04 | EM3: =Inputs!AP3 -> 0.04 | EN3: =Inputs!AQ3 -> 0.04 | EO3: =Inputs!AQ3 -> 0.04 | EP3: =Inputs!AR3 -> 0.04 | EQ3: =Inputs!AR3 -> 0.04 | ER3: =Inputs!AR3 -> 0.04 | ES3: =Inputs!AR3 -> 0.04 | ET3: =Inputs!AS3 -> 0.04 | EU3: =Inputs!AS3 -> 0.04 | EV3: =Inputs!AS3 -> 0.04 | EW3: =Inputs!AS3 -> 0.04 | EX3: =Inputs!AT3 -> 0.04 | EY3: =Inputs!AT3 -> 0.04 | EZ3: =Inputs!AT3 -> 0.04 | FA3: =Inputs!AT3 -> 0.04 | FB3: =Inputs!AU3 -> 0.04 | FC3: =Inputs!AU3 -> 0.04 | FD3: =Inputs!AU3 -> 0.04 | FE3: =Inputs!AU3 -> 0.04 | FF3: =Inputs!AV3 -> 0.04 | FG3: =Inputs!AV3 -> 0.04 | FH3: =Inputs!AV3 -> 0.04 | FI3: =Inputs!AV3 -> 0.04 | FJ3: =Inputs!AW3 -> 0.04 | FK3: =Inputs!AW3 -> 0.04 | FL3: =Inputs!AW3 -> 0.04 | FM3: =Inputs!AW3 -> 0.04 | FN3: =Inputs!AX3 -> 0.04 | FO3: =Inputs!AX3 -> 0.04 | FP3: =Inputs!AX3 -> 0.04 | FQ3: =Inputs!AX3 -> 0.04 | FR3: =Inputs!AY3 -> 0.04 | FS3: =Inputs!AY3 -> 0.04 | FT3: =Inputs!AY3 -> 0.04 | FU3: =Inputs!AY3 -> 0.04 | FV3: =Inputs!AZ3 -> 0.04 | FW3: =Inputs!AZ3 -> 0.04 | FX3: =Inputs!AZ3 -> 0.04 | FY3: =Inputs!AZ3 -> 0.04 | FZ3: =Inputs!BA3 -> 0.04 | GA3: =Inputs!BA3 -> 0.04 | GB3: =Inputs!BA3 -> 0.04 | GC3: =Inputs!BA3 -> 0.04 | GD3: =Inputs!BB3 -> 0.04 | GE3: =Inputs!BB3 -> 0.04 | GF3: =Inputs!BB3 -> 0.04 | GG3: =Inputs!BB3 -> 0.04 | GH3: =Inputs!BC3 -> 0.04 | GI3: =Inputs!BC3 -> 0.04 | GJ3: =Inputs!BC3 -> 0.04 | GK3: =Inputs!BC3 -> 0.04 | GL3: =Inputs!BD3 -> 0.04 | GM3: =Inputs!BD3 -> 0.04 | GN3: =Inputs!BD3 -> 0.04 | GO3: =Inputs!BD3 -> 0.04 | GP3: =Inputs!BE3 -> 0.04 | GQ3: =Inputs!BE3 -> 0.04 | GR3: =Inputs!BE3 -> 0.04 | GS3: =Inputs!BE3 -> 0.04 | GT3: =Inputs!BF3 -> 0.04 | GU3: =Inputs!BF3 -> 0.04 | GV3: =Inputs!BF3 -> 0.04 | GW3: =Inputs!BF3 -> 0.04 | GX3: =Inputs!BG3 -> 0.04 | GY3: =Inputs!BG3 -> 0.04 | GZ3: =Inputs!BG3 -> 0.04 | HA3: =Inputs!BG3 -> 0.04
A4: Общие | D4: CIB Research | F4: Инфляция - Рост индекса потребительских цен в США, в долларах США (USD, eop CPI) | G4: % | I4: EoY PCE, source: FX/IR team | J4: 0.029 | K4: 0.032 | L4: 0.026 | M4: 0.016 | N4: 0.015 | O4: 0.011 | P4: 0.015 | Q4: 0.024 | R4: 0.03 | S4: 0.021 | T4: 0.023 | U4: 0.019 | V4: 0.017 | W4: 0.033 | X4: 0.025 | Y4: 0.033 | Z4: 0.031 | AA4: 0.025 | AB4: 0.047 | AC4: 0.034 | AD4: 0.034 | AE4: 0.043 | AF4: 0.021 | AG4: 0.025 | AH4: 0.028 | AI4: 0.027 | AJ4: 0.028 | AK4: 0.041 | AL4: 0.04 | AM4: 0.05 | AN4: 0.049 | AO4: 0.001 | AP4: -0.004 | AQ4: -0.014 | AR4: -0.013 | AS4: 0.027 | AT4: 0.023 | AU4: 0.011 | AV4: 0.011 | AW4: 0.015 | AX4: 0.027 | AY4: 0.036 | AZ4: 0.039 | BA4: 0.03 | BB4: 0.027 | BC4: 0.017 | BD4: 0.02 | BE4: 0.017 | BF4: 0.015 | BG4: 0.018 | BH4: 0.012 | BI4: 0.015 | BJ4: 0.015122029 | BK4: 0.020723414 | BL4: 0.016579187 | BM4: 0.0075649327 | BN4: -0.00022030697 | BO4: 0.0017957028 | BP4: 8.8358094e-05 | BQ4: 0.0063871458 | BR4: 0.0089160605 | BS4: 0.010792812 | BT4: 0.015486393 | BU4: 0.020507924 | BV4: 0.024411943 | BW4: 0.016405633 | BX4: 0.021805592 | BY4: 0.021299357 | BZ4: 0.023309485 | CA4: 0.028075393 | CB4: 0.023320482 | CC4: 0.020023707 | CD4: 0.018831787 | CE4: 0.016711976 | CF4: 0.016845036 | CG4: 0.023195291 | CH4: 0.015231471 | CI4: 0.0070177162 | CJ4: 0.013730818 | CK4: 0.013049536 | CL4: 0.026186356 | CM4: 0.053150957 | CN4: 0.053610217 | CO4: 0.071765966 | CP4: 0.085474376 | CQ4: 0.089897548 | CR4: 0.081982851 | CS4: 0.064115004 | CT4: 0.049350904 | CU4: 0.030532585 | CV4: 0.036940422 | CW4: 0.03323156 | CX4: 0.034751249 | CY4: 0.029756235 | CZ4: 0.024075194 | DA4: 0.028965881 | DB4: 0.024055926 | DC4: 0.026726904 | DD4: 0.030227089 | DE4: 0.026899449 | DF4: 0.035429288 | DG4: 0.037169706 | DH4: 0.028660294 | DI4: 0.027326387 | DJ4: 0.023346989 | DK4: 0.021743947 | DL4: 0.027986742 | DM4: 0.026069089 | DN4: 0.021271763 | DO4: 0.020625551 | DP4: 0.021668128 | DQ4: 0.022921913 | DR4: 0.02252651 | DS4: 0.021532968 | DT4: 0.020466105 | DU4: 0.01939121 | DV4: 0.019719505 | DW4: 0.020552486 | DX4: 0.021448954 | DY4: 0.02235396 | DZ4: =Inputs!AN4 -> 0.02 | EA4: =Inputs!AN4 -> 0.02 | EB4: =Inputs!AN4 -> 0.02 | EC4: =Inputs!AN4 -> 0.02 | ED4: =Inputs!AO4 -> 0.02 | EE4: =Inputs!AO4 -> 0.02 | EF4: =Inputs!AO4 -> 0.02 | EG4: =Inputs!AO4 -> 0.02 | EH4: =Inputs!AP4 -> 0.02 | EI4: =Inputs!AP4 -> 0.02 | EJ4: =Inputs!AP4 -> 0.02 | EK4: =Inputs!AP4 -> 0.02 | EL4: =Inputs!AQ4 -> 0.02 | EM4: =Inputs!AP4 -> 0.02 | EN4: =Inputs!AQ4 -> 0.02 | EO4: =Inputs!AQ4 -> 0.02 | EP4: =Inputs!AR4 -> 0.02 | EQ4: =Inputs!AR4 -> 0.02 | ER4: =Inputs!AR4 -> 0.02 | ES4: =Inputs!AR4 -> 0.02 | ET4: =Inputs!AS4 -> 0.02 | EU4: =Inputs!AS4 -> 0.02 | EV4: =Inputs!AS4 -> 0.02 | EW4: =Inputs!AS4 -> 0.02 | EX4: =Inputs!AT4 -> 0.02 | EY4: =Inputs!AT4 -> 0.02 | EZ4: =Inputs!AT4 -> 0.02 | FA4: =Inputs!AT4 -> 0.02 | FB4: =Inputs!AU4 -> 0.02 | FC4: =Inputs!AU4 -> 0.02 | FD4: =Inputs!AU4 -> 0.02 | FE4: =Inputs!AU4 -> 0.02 | FF4: =Inputs!AV4 -> 0.02 | FG4: =Inputs!AV4 -> 0.02 | FH4: =Inputs!AV4 -> 0.02 | FI4: =Inputs!AV4 -> 0.02 | FJ4: =Inputs!AW4 -> 0.02 | FK4: =Inputs!AW4 -> 0.02 | FL4: =Inputs!AW4 -> 0.02 | FM4: =Inputs!AW4 -> 0.02 | FN4: =Inputs!AX4 -> 0.02 | FO4: =Inputs!AX4 -> 0.02 | FP4: =Inputs!AX4 -> 0.02 | FQ4: =Inputs!AX4 -> 0.02 | FR4: =Inputs!AY4 -> 0.02 | FS4: =Inputs!AY4 -> 0.02 | FT4: =Inputs!AY4 -> 0.02 | FU4: =Inputs!AY4 -> 0.02 | FV4: =Inputs!AZ4 -> 0.02 | FW4: =Inputs!AZ4 -> 0.02 | FX4: =Inputs!AZ4 -> 0.02 | FY4: =Inputs!AZ4 -> 0.02 | FZ4: =Inputs!BA4 -> 0.02 | GA4: =Inputs!BA4 -> 0.02 | GB4: =Inputs!BA4 -> 0.02 | GC4: =Inputs!BA4 -> 0.02 | GD4: =Inputs!BB4 -> 0.02 | GE4: =Inputs!BB4 -> 0.02 | GF4: =Inputs!BB4 -> 0.02 | GG4: =Inputs!BB4 -> 0.02 | GH4: =Inputs!BC4 -> 0.02 | GI4: =Inputs!BC4 -> 0.02 | GJ4: =Inputs!BC4 -> 0.02 | GK4: =Inputs!BC4 -> 0.02 | GL4: =Inputs!BD4 -> 0.02 | GM4: =Inputs!BD4 -> 0.02 | GN4: =Inputs!BD4 -> 0.02 | GO4: =Inputs!BD4 -> 0.02 | GP4: =Inputs!BE4 -> 0.02 | GQ4: =Inputs!BE4 -> 0.02 | GR4: =Inputs!BE4 -> 0.02 | GS4: =Inputs!BE4 -> 0.02 | GT4: =Inputs!BF4 -> 0.02 | GU4: =Inputs!BF4 -> 0.02 | GV4: =Inputs!BF4 -> 0.02 | GW4: =Inputs!BF4 -> 0.02 | GX4: =Inputs!BG4 -> 0.02 | GY4: =Inputs!BG4 -> 0.02 | GZ4: =Inputs!BG4 -> 0.02 | HA4: =Inputs!BG4 -> 0.02
A5: Общие | D5: ЦМИ | F5: Инфляция - Рост индекса цен производителей (RUB, eop PPI) | G5: % | I5: С 2021 года прогноз CIB | J5: 0.237 | K5: 0.22 | L5: 0.143 | M5: 0.083 | N5: 0.047 | O5: 0.077 | P5: 0.136 | Q5: 0.177 | R5: 0.222 | S5: 0.154 | T5: 0.151 | U5: 0.125 | V5: 0.158 | W5: 0.242 | X5: 0.242 | Y5: 0.288 | Z5: 0.194 | AA5: 0.198 | AB5: 0.178 | AC5: 0.154 | AD5: 0.167 | AE5: 0.119 | AF5: 0.095 | AG5: 0.104 | AH5: 0.031 | AI5: 0.126 | AJ5: 0.086 | AK5: 0.251 | AL5: 0.274 | AM5: 0.281 | AN5: 0.257 | AO5: -0.07 | AP5: -0.028 | AQ5: -0.094 | AR5: -0.055 | AS5: 0.139 | AT5: 0.192 | AU5: 0.098 | AV5: 0.059 | AW5: 0.167 | AX5: 0.185 | AY5: 0.167 | AZ5: 0.158 | BA5: 0.113 | BB5: 0.069 | BC5: 0.043 | BD5: 0.1 | BE5: 0.052 | BF5: 0.043 | BG5: 0.035 | BH5: 0.02 | BI5: 0.035 | BJ5: 0.048 | BK5: 0.092 | BL5: 0.039 | BM5: 0.063 | BN5: 0.142 | BO5: 0.144 | BP5: 0.144 | BQ5: 0.121 | BR5: 0.021 | BS5: 0.056 | BT5: 0.044 | BU5: 0.075 | BV5: 0.113 | BW5: 0.029 | BX5: 0.068 | BY5: 0.084 | BZ5: 0.0483 | CA5: 0.1606 | CB5: 0.1439 | CC5: 0.1171 | CD5: 0.109 | CE5: 0.0413 | CF5: -0.0122 | CG5: -0.0426 | CH5: -0.032 | CI5: -0.0829 | CJ5: -0.0002 | CK5: 0.0356 | CL5: 0.1596 | CM5: 0.3104 | CN5: 0.2627 | CO5: 0.2852 | CP5: 0.27736565 | CQ5: 0.12171299 | CR5: 0.04446833 | CS5: -0.033181437 | CT5: -0.1069 | CU5: 0.0001 | CV5: 0.1671 | CW5: 0.1916 | CX5: 0.1914 | CY5: 0.14 | CZ5: 0.0557 | DA5: 0.0791 | DB5: 0.059 | DC5: 0.0005 | DD5: -0.0039 | DE5: -0.0328 | DF5: -0.018 | DG5: 0.104 | DH5: 0.080344606 | DI5: 0.12373075 | DJ5: 0.11202318 | DK5: 0.035958275 | DL5: 0.050757244 | DM5: 0.048265541 | DN5: 0.069083849 | DO5: 0.083098045 | DP5: 0.089741434 | DQ5: 0.087119187 | DR5: 0.082315983 | DS5: 0.068387271 | DT5: 0.057811213 | DU5: 0.053103144 | DV5: 0.055142161 | DW5: 0.056857642 | DX5: 0.056908205 | DY5: 0.056887074 | DZ5: =Inputs!AN5 -> 0.04 | EA5: =Inputs!AN5 -> 0.04 | EB5: =Inputs!AN5 -> 0.04 | EC5: =Inputs!AN5 -> 0.04 | ED5: =Inputs!AO5 -> 0.04 | EE5: =Inputs!AO5 -> 0.04 | EF5: =Inputs!AO5 -> 0.04 | EG5: =Inputs!AO5 -> 0.04 | EH5: =Inputs!AP5 -> 0.04 | EI5: =Inputs!AP5 -> 0.04 | EJ5: =Inputs!AP5 -> 0.04 | EK5: =Inputs!AP5 -> 0.04 | EL5: =Inputs!AQ5 -> 0.04 | EM5: =Inputs!AP5 -> 0.04 | EN5: =Inputs!AQ5 -> 0.04 | EO5: =Inputs!AQ5 -> 0.04 | EP5: =Inputs!AR5 -> 0.04 | EQ5: =Inputs!AR5 -> 0.04 | ER5: =Inputs!AR5 -> 0.04 | ES5: =Inputs!AR5 -> 0.04 | ET5: =Inputs!AS5 -> 0.04 | EU5: =Inputs!AS5 -> 0.04 | EV5: =Inputs!AS5 -> 0.04 | EW5: =Inputs!AS5 -> 0.04 | EX5: =Inputs!AT5 -> 0.04 | EY5: =Inputs!AT5 -> 0.04 | EZ5: =Inputs!AT5 -> 0.04 | FA5: =Inputs!AT5 -> 0.04 | FB5: =Inputs!AU5 -> 0.04 | FC5: =Inputs!AU5 -> 0.04 | FD5: =Inputs!AU5 -> 0.04 | FE5: =Inputs!AU5 -> 0.04 | FF5: =Inputs!AV5 -> 0.04 | FG5: =Inputs!AV5 -> 0.04 | FH5: =Inputs!AV5 -> 0.04 | FI5: =Inputs!AV5 -> 0.04 | FJ5: =Inputs!AW5 -> 0.04 | FK5: =Inputs!AW5 -> 0.04 | FL5: =Inputs!AW5 -> 0.04 | FM5: =Inputs!AW5 -> 0.04 | FN5: =Inputs!AX5 -> 0.04 | FO5: =Inputs!AX5 -> 0.04 | FP5: =Inputs!AX5 -> 0.04 | FQ5: =Inputs!AX5 -> 0.04 | FR5: =Inputs!AY5 -> 0.04 | FS5: =Inputs!AY5 -> 0.04 | FT5: =Inputs!AY5 -> 0.04 | FU5: =Inputs!AY5 -> 0.04 | FV5: =Inputs!AZ5 -> 0.04 | FW5: =Inputs!AZ5 -> 0.04 | FX5: =Inputs!AZ5 -> 0.04 | FY5: =Inputs!AZ5 -> 0.04 | FZ5: =Inputs!BA5 -> 0.04 | GA5: =Inputs!BA5 -> 0.04 | GB5: =Inputs!BA5 -> 0.04 | GC5: =Inputs!BA5 -> 0.04 | GD5: =Inputs!BB5 -> 0.04 | GE5: =Inputs!BB5 -> 0.04 | GF5: =Inputs!BB5 -> 0.04 | GG5: =Inputs!BB5 -> 0.04 | GH5: =Inputs!BC5 -> 0.04 | GI5: =Inputs!BC5 -> 0.04 | GJ5: =Inputs!BC5 -> 0.04 | GK5: =Inputs!BC5 -> 0.04 | GL5: =Inputs!BD5 -> 0.04 | GM5: =Inputs!BD5 -> 0.04 | GN5: =Inputs!BD5 -> 0.04 | GO5: =Inputs!BD5 -> 0.04 | GP5: =Inputs!BE5 -> 0.04 | GQ5: =Inputs!BE5 -> 0.04 | GR5: =Inputs!BE5 -> 0.04 | GS5: =Inputs!BE5 -> 0.04 | GT5: =Inputs!BF5 -> 0.04 | GU5: =Inputs!BF5 -> 0.04 | GV5: =Inputs!BF5 -> 0.04 | GW5: =Inputs!BF5 -> 0.04 | GX5: =Inputs!BG5 -> 0.04 | GY5: =Inputs!BG5 -> 0.04 | GZ5: =Inputs!BG5 -> 0.04 | HA5: =Inputs!BG5 -> 0.04
A6: Общие | D6: ЦМИ | F6: Инфляция - Дефлятор ВВП (RUB, GDP Deflator) | G6: % | I6: =0.8CPI+0.2PPI; С 2021 года прогноз CIB | BJ6: 0.057 | BK6: 0.077 | BL6: 0.08 | BM6: 0.084 | BN6: 0.084 | BO6: 0.074 | BP6: 0.089 | BQ6: 0.075 | BR6: 0.034 | BS6: 0.042 | BT6: 0.025 | BU6: 0.039 | BV6: 0.069 | BW6: 0.042 | BX6: 0.041 | BY6: 0.058 | BZ6: 0.064 | CA6: 0.109 | CB6: 0.117 | CC6: 0.105 | CD6: 0.08 | CE6: 0.052 | CF6: 0.014 | CG6: -0.003 | CH6: -0.0046325265 | CI6: -0.036674774 | CJ6: 0.013999643 | CK6: 0.053859177 | CL6: 0.11663621 | CM6: 0.20946845 | CN6: 0.21820742 | CO6: 0.17987697 | CP6: 0.28973736 | CQ6: 0.22212763 | CR6: 0.1454369 | CS6: 0.10577648 | CT6: 0.0207582 | CU6: 0.0965861 | CV6: 0.1424466 | CW6: 0.1510461 | CX6: 0.1275925 | CY6: 0.0807596 | CZ6: 0.0817403 | DA6: 0.0676184 | DB6: 0.0256859 | DC6: 0.0606908 | DD6: 0.0421024 | DE6: 0.041603 | DF6: 0.06193409 | DG6: 0.074143104 | DH6: 0.097730764 | DI6: 0.086055585 | DJ6: 0.053870765 | DK6: 0.038267441 | DL6: 0.018347743 | DM6: 0.012447417 | DN6: =0.8*DN3+0.2*DN5 -> 0.04852842 | DO6: =0.8*DO3+0.2*DO5 -> 0.054277776 | DP6: =0.8*DP3+0.2*DP5 -> 0.051647987 | DQ6: =0.8*DQ3+0.2*DQ5 -> 0.049464001 | DR6: =0.8*DR3+0.2*DR5 -> 0.048838594 | DS6: =0.8*DS3+0.2*DS5 -> 0.046052689 | DT6: =0.8*DT3+0.2*DT5 -> 0.043439954 | DU6: =0.8*DU3+0.2*DU5 -> 0.04249834 | ... HA6: =0.8*HA3+0.2*HA5 -> 0.04
A7: Общие | D7: Расчет | F7: Курс рубля к доллару США в конце года (eop USD/RUB) | G7: $/руб | I7: 2015-17 модель ЦМИ c ценой на нефть CIB Research, после - CIB Research, с 2019 года прогноз CIB; =предыдущий год*1.02 | J7: 28.76 | K7: 29.147 | L7: 29.467 | M7: 30.505 | N7: 31.21 | O7: 31.475 | P7: 31.69 | Q7: 31.955 | R7: 31.3863 | S7: 30.3655 | T7: 30.587 | U7: 29.2425 | V7: 28.519 | W7: 29.0698 | X7: 29.2229 | Y7: 27.72 | Z7: 27.8621 | AA7: 28.63 | AB7: 28.4977 | AC7: 28.7414 | AD7: 27.705 | AE7: 26.8455 | AF7: 26.7958 | AG7: 26.3255 | AH7: 25.986 | AI7: 25.7449 | AJ7: 24.8588 | AK7: 24.6006 | AL7: 23.4929 | AM7: 23.4446 | AN7: 25.6439 | AO7: 29.4027 | AP7: 33.954 | AQ7: 31.1527 | AR7: 30.0154 | AS7: 30.035 | AT7: 29.4205 | AU7: 31.2095 | AV7: 30.535 | AW7: 30.537 | AX7: 28.418 | AY7: 27.8693 | AZ7: 32.184 | BA7: 32.137 | BB7: 29.347 | BC7: 32.4245 | BD7: 31.18 | BE7: 30.525 | BF7: 31.0564 | BG7: 32.8395 | BH7: 32.3906 | BI7: 32.8696 | BJ7: 35.6871 | BK7: 33.6306 | BL7: 39.3866 | BM7: 56.2584 | BN7: 58.4643 | BO7: 55.524 | BP7: 66.2367 | BQ7: 72.8827 | BR7: 67.6076 | BS7: 64.2575 | BT7: 63.1581 | BU7: 60.6569 | BV7: 56.3779 | BW7: 59.0855 | BX7: 58.0169 | BY7: 57.6002 | BZ7: 57.2649 | CA7: 62.7565 | CB7: 65.5906 | CC7: 69.4706 | CD7: 64.7347 | CE7: 63.0756 | CF7: 64.4156 | CG7: 61.9057 | CH7: 77.7325 | CI7: 69.9513 | CJ7: 79.6845 | CK7: 73.8757 | CL7: 75.7023 | CM7: 72.3723 | CN7: 72.7608 | CO7: 74.2926 | CP7: 84.1 | CQ7: 51.158 | CR7: 57.413 | CS7: 70.3375 | CT7: 77.09 | CU7: 87.03 | CV7: 97.41 | CW7: 89.69 | CX7: 92.37 | CY7: 85.75 | CZ7: 92.71 | DA7: 101.68 | DB7: 83.68 | DC7: 78.47 | DD7: 82.87 | DE7: 78.23 | DF7: 81.2955 | DG7: 77.7539 | DH7: 84.253982 | DI7: 88.047138 | DJ7: 89.803836 | DK7: 91.087323 | DL7: 92.181412 | DM7: 93.201775 | DN7: 94.198616 | DO7: 95.193278 | DP7: 96.194511 | DQ7: 97.205694 | DR7: 98.228 | DS7: 99.261758 | DT7: 100.30701 | DU7: 101.36373 | DV7: 102.4319 | DW7: 103.51155 | DX7: 104.60272 | DY7: 105.70549 | DZ7: =(EC7-DY7)/4+DY7 -> 105.76889 | EA7: =(EC7-DY7)/4*2+DY7 -> 105.8323 | EB7: =(EC7-DY7)/4*3+DY7 -> 105.8957 | EC7: =Inputs!AN7 -> 105.95911 | ED7: =(EG7-EC7)/4+EC7 -> 106.4889 | EE7: =(EG7-EC7)/4*2+EC7 -> 107.0187 | EF7: =(EG7-EC7)/4*3+EC7 -> 107.54849 | EG7: =Inputs!AO7 -> 108.07829 | EH7: =(EK7-EG7)/4+EG7 -> 108.61868 | EI7: =(EK7-EG7)/4*2+EG7 -> 109.15907 | EJ7: =(EK7-EG7)/4*3+EG7 -> 109.69946 | EK7: =Inputs!AP7 -> 110.23985 | EL7: =(EO7-EK7)/4+EK7 -> 110.79105 | EM7: =(EO7-EK7)/4*2+EK7 -> 111.34225 | EN7: =(EO7-EK7)/4*3+EK7 -> 111.89345 | EO7: =Inputs!AQ7 -> 112.44465 | EP7: =(ES7-EO7)/4+EO7 -> 113.00687 | EQ7: =(ES7-EO7)/4*2+EO7 -> 113.5691 | ER7: =(ES7-EO7)/4*3+EO7 -> 114.13132 | ES7: =Inputs!AR7 -> 114.69354 | ET7: =(EW7-ES7)/4+ES7 -> 115.26701 | EU7: =(EW7-ES7)/4*2+ES7 -> 115.84048 | EV7: =(EW7-ES7)/4*3+ES7 -> 116.41395 | EW7: =Inputs!AS7 -> 116.98741 | EX7: =(FA7-EW7)/4+EW7 -> 117.57235 | EY7: =(FA7-EW7)/4*2+EW7 -> 118.15729 | EZ7: =(FA7-EW7)/4*3+EW7 -> 118.74223 | FA7: =Inputs!AT7 -> 119.32716 | FB7: =(FE7-FA7)/4+FA7 -> 119.9238 | FC7: =(FE7-FA7)/4*2+FA7 -> 120.52043 | FD7: =(FE7-FA7)/4*3+FA7 -> 121.11707 | FE7: =Inputs!AU7 -> 121.71371 | FF7: =(FI7-FE7)/4+FE7 -> 122.32227 | FG7: =(FI7-FE7)/4*2+FE7 -> 122.93084 | FH7: =(FI7-FE7)/4*3+FE7 -> 123.53941 | FI7: =Inputs!AV7 -> 124.14798 | FJ7: =(FM7-FI7)/4+FI7 -> 124.76872 | FK7: =(FM7-FI7)/4*2+FI7 -> 125.38946 | FL7: =(FM7-FI7)/4*3+FI7 -> 126.0102 | FM7: =Inputs!AW7 -> 126.63094 | FN7: =(FQ7-FM7)/4+FM7 -> 127.26409 | FO7: =(FQ7-FM7)/4*2+FM7 -> 127.89725 | FP7: =(FQ7-FM7)/4*3+FM7 -> 128.5304 | FQ7: =Inputs!AX7 -> 129.16356 | FR7: =(FU7-FQ7)/4+FQ7 -> 129.80938 | FS7: =(FU7-FQ7)/4*2+FQ7 -> 130.45519 | FT7: =(FU7-FQ7)/4*3+FQ7 -> 131.10101 | FU7: =Inputs!AY7 -> 131.74683 | FV7: =(FY7-FU7)/4+FU7 -> 132.40556 | FW7: =(FY7-FU7)/4*2+FU7 -> 133.0643 | FX7: =(FY7-FU7)/4*3+FU7 -> 133.72303 | FY7: =Inputs!AZ7 -> 134.38177 | FZ7: =(GC7-FY7)/4+FY7 -> 135.05368 | GA7: =(GC7-FY7)/4*2+FY7 -> 135.72558 | GB7: =(GC7-FY7)/4*3+FY7 -> 136.39749 | GC7: =Inputs!BA7 -> 137.0694 | GD7: =(GG7-GC7)/4+GC7 -> 137.75475 | GE7: =(GG7-GC7)/4*2+GC7 -> 138.4401 | GF7: =(GG7-GC7)/4*3+GC7 -> 139.12544 | GG7: =Inputs!BB7 -> 139.81079 | GH7: =(GK7-GG7)/4+GG7 -> 140.50984 | GI7: =(GK7-GG7)/4*2+GG7 -> 141.2089 | GJ7: =(GK7-GG7)/4*3+GG7 -> 141.90795 | GK7: =Inputs!BC7 -> 142.60701 | GL7: =(GO7-GK7)/4+GK7 -> 143.32004 | GM7: =(GO7-GK7)/4*2+GK7 -> 144.03308 | GN7: =(GO7-GK7)/4*3+GK7 -> 144.74611 | GO7: =Inputs!BD7 -> 145.45915 | GP7: =(GS7-GO7)/4+GO7 -> 146.18644 | GQ7: =(GS7-GO7)/4*2+GO7 -> 146.91374 | GR7: =(GS7-GO7)/4*3+GO7 -> 147.64103 | GS7: =Inputs!BE7 -> 148.36833 | GT7: =(GW7-GS7)/4+GS7 -> 149.11017 | GU7: =(GW7-GS7)/4*2+GS7 -> 149.85201 | GV7: =(GW7-GS7)/4*3+GS7 -> 150.59385 | GW7: =Inputs!BF7 -> 151.3357 | GX7: =(HA7-GW7)/4+GW7 -> 152.09237 | GY7: =(HA7-GW7)/4*2+GW7 -> 152.84905 | GZ7: =(HA7-GW7)/4*3+GW7 -> 153.60573 | HA7: =Inputs!BG7 -> 154.36241
A8: Общие | D8: Расчет | F8: Курс рубля к EUR в конце года (eop EUR/RUB) | G8: EUR/руб | I8: =EUR/USD*курс доллара | J8: 25.2891 | K8: 24.6932 | L8: 26.8106 | M8: 27.1421 | N8: 27.1503 | O8: 31.0662 | P8: 31.3235 | Q8: 33.5123 | R8: 34.2366 | S8: 34.9359 | T8: 35.6573 | U8: 36.8234 | V8: 35.1254 | W8: 35.4697 | X8: 36.3425 | Y8: 37.5689 | Z8: 36.1357 | AA8: 34.67 | AB8: 34.2772 | AC8: 34.0542 | AD8: 33.5703 | AE8: 34.3354 | AF8: 33.9589 | AG8: 34.7483 | AH8: 34.707 | AI8: 34.8609 | AJ8: 35.4542 | AK8: 35.9442 | AL8: 37.0882 | AM8: 36.9345 | AN8: 36.1407 | AO8: 42.6587 | AP8: 44.9904 | AQ8: 43.7165 | AR8: 43.9365 | AS8: 43.0244 | AT8: 39.7668 | AU8: 38.2568 | AV8: 41.6154 | AW8: 40.8504 | AX8: 40.2377 | AY8: 40.4245 | AZ8: 43.1635 | BA8: 41.736 | BB8: 39.2407 | BC8: 41.0478 | BD8: 40.1366 | BE8: 40.3115 | BF8: 39.8259 | BG8: 42.72 | BH8: 43.7919 | BI8: 45.5995 | BJ8: 48.3055 | BK8: 46.5445 | BL8: 50.0916 | BM8: 73.5065 | BN8: 62.4678 | BO8: 61.6005 | BP8: 73.1696 | BQ8: 79.6995 | BR8: 75.9913 | BS8: 71.124 | BT8: 70.633 | BU8: 64.6778 | BV8: 59.4954 | BW8: 67.0103 | BX8: 68.0269 | BY8: 69.1837 | BZ8: 70.1779 | CA8: 73.3411 | CB8: 76.1155 | CC8: =Inputs!AA8 -> 79.4605 | CD8: 73.7145 | CE8: 71.9157 | CF8: 70.6363 | CG8: =Inputs!AB8 -> 69.3406 | CH8: 86.7152 | CI8: 79.9539 | CJ8: 91.0048 | CK8: =Inputs!AC8 -> 90.6824 | CL8: 88.717 | CM8: 86.7363 | CN8: 84.2151 | CO8: =Inputs!AD8 -> 84.0695 | CP8: 93.696 | CQ8: 53.858 | CR8: =CR7*CR36 -> 55.41 | CS8: =Inputs!AE8 -> 75.6553 | CT8: 83.7639 | CU8: 95.1052 | CV8: 102.0979 | CW8: =Inputs!AF8 -> 99.2 | CX8: 99.5299 | CY8: 92.4184 | CZ8: 103.4694 | DA8: =Inputs!AG8 -> 106.1028 | DB8: =DB7*DB36 -> 89.653907 | DC8: =DC7*DC36 -> 92.280264 | DD8: =DD7*DD36 -> 97.143813 | DE8: 92.097683 | DF8: =DF7*DF36 -> 93.636157 | DG8: =DG7*DG36 -> 88.771628 | DH8: =DH7*DH36 -> 98.135785 | DI8: =DI7*DI36 -> 102.13468 | DJ8: =DJ7*DJ36 -> 103.83661 | DK8: =DK7*DK36 -> 105.05623 | DL8: =DL7*DL36 -> 106.12605 | DM8: =DM7*DM36 -> 107.18204 | ... FU8: =FU7*FU36 -> 151.49251 | FV8: =FV7*FY36 -> 152.24997 | FW8: =FW7*FW36 -> 153.00743 | FX8: =FX7*FX36 -> 153.7649 | FY8: =FY7*FY36 -> 154.52236 | FZ8: =FZ7*FZ36 -> 155.29497 | GA8: =GA7*GA36 -> 156.06758 | GB8: =GB7*GB36 -> 156.8402 | GC8: =GC7*GC36 -> 157.61281 | GD8: =GD7*GD36 -> 158.40087 | ... HA8: =HA7*HA36 -> 177.49762
